Workbook
Name _Toc514914552: '03. Capacitación Y Eventos'!#REF!

Sheet RESUMEN
E2: CONVOCATORIA DE EMERGENCIA PARA LA RECUPERACIÓN Y GENERACIÓN DE CAPACIDADES TRANSFORMADORAS, EN EL MARCO DEL DECRETO 1414 DE 17 DE SEPTIEMBRE DE 2026. ANEXO 3. PRESUPUESTO
B4: Código de registro SIGP: 143329 · Implementación de una red IoT híbrida Edge-Cloud y gemelo digital para la gestión anticipada del riesgo por material particulado posterremoto
C6: RESUMEN DEL PRESUPUESTO
B7: Cuadro guía de entidades, actividades y montos a ejecutar: fila 50 de esta hoja (debajo de la firma).
B8: RESUMEN
B9: Item | C9: Rubro | D9: CONTRAPARTIDA | N9: SGR | O9: TOTAL
D10: Entidad 1 – Universidad Santo Tomás de Colombia, sede Villavicencio — entidad proponente y ejecutora | F10: Entidad 2 – Municipio de Manizales (Caldas) | H10: Entidad 3 – Municipio de Calarcá (Quindío) | J10: Entidad 4 – Avanciencia — oficina de transferencia de resultados de investigación (OTRI) [razón social y NIT por diligenciar] | L10: Entidad 5 – Gestión y Medio Ambiente — aliado tecnológico [razón social y NIT por diligenciar] | N10: Relacione los rubros con cargo a la asignación para la CTeI del SGR
D11: Especie | E11: Efectivo | F11: Especie | G11: Efectivo | H11: Especie | I11: Efectivo | J11: Especie | K11: Efectivo | L11: Especie | M11: Efectivo | N11: Efectivo
B12: 1 | C12: Talento humano | D12: ='01. Talento Humano'!$K$38 -> 800000000 | E12: ='01. Talento Humano'!$L$38 -> 0 | F12: ='01. Talento Humano'!$M$38 -> 60000000 | G12: ='01. Talento Humano'!$N$38 -> 0 | H12: ='01. Talento Humano'!$O$38 -> 60000000 | I12: ='01. Talento Humano'!$P$38 -> 0 | J12: ='01. Talento Humano'!$Q$38 -> 150000000 | K12: ='01. Talento Humano'!$R$38 -> 0 | L12: ='01. Talento Humano'!$S$38 -> 0 | M12: ='01. Talento Humano'!$T$38 -> 0 | N12: ='01. Talento Humano'!$U$38 -> 5256515630 | O12: =N12+(D12+E12+F12+G12+H12+I12+J12+K12+L12+M12) -> 6326515630
B13: 2 | C13: Equipos y software | D13: ='02. Equipos y Software'!$I$37 -> 444000000 | E13: ='02. Equipos y Software'!$J$37 -> 0 | F13: ='02. Equipos y Software'!$K$37 -> 0 | G13: ='02. Equipos y Software'!$L$37 -> 0 | H13: ='02. Equipos y Software'!$M$37 -> 0 | I13: ='02. Equipos y Software'!$N$37 -> 0 | J13: ='02. Equipos y Software'!$O$37 -> 0 | K13: ='02. Equipos y Software'!$P$37 -> 0 | L13: ='02. Equipos y Software'!$Q$37 -> 110000000 | M13: ='02. Equipos y Software'!$R$37 -> 0 | N13: ='02. Equipos y Software'!$S$37 -> 5464885709 | O13: =N13+(D13+E13+F13+G13+H13+I13+J13+K13+L13+M13) -> 6018885709
B14: 3 | C14: Capacitación y eventos | D14: ='03. Capacitación Y Eventos'!$F$20 -> 0 | E14: ='03. Capacitación Y Eventos'!$G$20 -> 0 | F14: ='03. Capacitación Y Eventos'!$H$20 -> 0 | G14: ='03. Capacitación Y Eventos'!$I$20 -> 0 | H14: ='03. Capacitación Y Eventos'!$J$20 -> 0 | I14: ='03. Capacitación Y Eventos'!$K$20 -> 0 | J14: ='03. Capacitación Y Eventos'!$L$20 -> 0 | K14: ='03. Capacitación Y Eventos'!$M$20 -> 0 | L14: ='03. Capacitación Y Eventos'!$N$20 -> 0 | M14: ='03. Capacitación Y Eventos'!$O$20 -> 0 | N14: ='03. Capacitación Y Eventos'!$P$20 -> 416968410 | O14: =N14+(D14+E14+F14+G14+H14+I14+J14+K14+L14+M14) -> 416968410
B15: 4 | C15: Servicios tecnológicos y pruebas | D15: ='04. Servicios Tecnologicos'!$H$36 -> 0 | E15: ='04. Servicios Tecnologicos'!$I$36 -> 0 | F15: ='04. Servicios Tecnologicos'!$J$36 -> 0 | G15: ='04. Servicios Tecnologicos'!$K$36 -> 0 | H15: ='04. Servicios Tecnologicos'!$L$36 -> 0 | I15: ='04. Servicios Tecnologicos'!$M$36 -> 0 | J15: ='04. Servicios Tecnologicos'!$N$36 -> 0 | K15: ='04. Servicios Tecnologicos'!$O$36 -> 0 | L15: ='04. Servicios Tecnologicos'!$P$36 -> 0 | M15: ='04. Servicios Tecnologicos'!$Q$36 -> 0 | N15: ='04. Servicios Tecnologicos'!$R$36 -> 1396651250 | O15: =N15+(D15+E15+F15+G15+H15+I15+J15+K15+L15+M15) -> 1396651250
B16: 5 | C16: Materiales, insumos y documentación | D16: ='05. Materiales, Insumos y Doc.'!$J$33 -> 0 | E16: ='05. Materiales, Insumos y Doc.'!$K$33 -> 0 | F16: ='05. Materiales, Insumos y Doc.'!$L$33 -> 0 | G16: ='05. Materiales, Insumos y Doc.'!$M$33 -> 0 | H16: ='05. Materiales, Insumos y Doc.'!$N$33 -> 0 | I16: ='05. Materiales, Insumos y Doc.'!$O$33 -> 0 | J16: ='05. Materiales, Insumos y Doc.'!$P$33 -> 0 | K16: ='05. Materiales, Insumos y Doc.'!$Q$33 -> 0 | L16: ='05. Materiales, Insumos y Doc.'!$R$33 -> 0 | M16: ='05. Materiales, Insumos y Doc.'!$S$33 -> 0 | N16: ='05. Materiales, Insumos y Doc.'!$T$33 -> 255154480 | O16: =N16+(D16+E16+F16+G16+H16+I16+J16+K16+L16+M16) -> 255154480
B17: 6 | C17: Protección del conocimiento y divulgación | D17: ='06.Protección conocimiento y Di'!$H$19 -> 0 | E17: ='06.Protección conocimiento y Di'!$I$19 -> 0 | F17: ='06.Protección conocimiento y Di'!$J$19 -> 0 | G17: ='06.Protección conocimiento y Di'!$K$19 -> 0 | H17: ='06.Protección conocimiento y Di'!$L$19 -> 0 | I17: ='06.Protección conocimiento y Di'!$M$19 -> 0 | J17: ='06.Protección conocimiento y Di'!$N$19 -> 0 | K17: ='06.Protección conocimiento y Di'!$O$19 -> 0 | L17: ='06.Protección conocimiento y Di'!$P$19 -> 0 | M17: ='06.Protección conocimiento y Di'!$Q$19 -> 0 | N17: ='06.Protección conocimiento y Di'!$R$19 -> 259953486 | O17: =N17+(D17+E17+F17+G17+H17+I17+J17+K17+L17+M17) -> 259953486
B18: 7 | C18: Gastos de viaje | D18: ='08. Gastos de viaje'!$J$52 -> 0 | E18: ='08. Gastos de viaje'!$K$52 -> 0 | F18: ='08. Gastos de viaje'!$L$52 -> 0 | G18: ='08. Gastos de viaje'!$M$52 -> 0 | H18: ='08. Gastos de viaje'!$N$52 -> 0 | I18: ='08. Gastos de viaje'!$O$52 -> 0 | J18: ='08. Gastos de viaje'!$P$52 -> 0 | K18: ='08. Gastos de viaje'!$Q$52 -> 0 | L18: ='08. Gastos de viaje'!$R$52 -> 0 | M18: ='08. Gastos de viaje'!$S$52 -> 150000000 | N18: ='08. Gastos de viaje'!$T$52 -> 457276250 | O18: =N18+(D18+E18+F18+G18+H18+I18+J18+K18+L18+M18) -> 607276250
B19: 8 | C19: Infraestructura | D19: ='07. Infraestructura'!$F$18 -> 0 | E19: ='07. Infraestructura'!$G$18 -> 0 | F19: ='07. Infraestructura'!$H$18 -> 0 | G19: ='07. Infraestructura'!$I$18 -> 0 | H19: ='07. Infraestructura'!$J$18 -> 0 | I19: ='07. Infraestructura'!$K$18 -> 0 | J19: ='07. Infraestructura'!$L$18 -> 0 | K19: ='07. Infraestructura'!$M$18 -> 0 | L19: ='07. Infraestructura'!$N$18 -> 0 | M19: ='07. Infraestructura'!$O$18 -> 0 | N19: ='07. Infraestructura'!$P$18 -> 132000000 | O19: =N19+(D19+E19+F19+G19+H19+I19+J19+K19+L19+M19) -> 132000000
B20: 9 | C20: Administrativos | D20: ='09. Administrativos '!$F$17 -> 0 | E20: ='09. Administrativos '!$G$17 -> 0 | F20: ='09. Administrativos '!$H$17 -> 0 | G20: ='09. Administrativos '!$I$17 -> 0 | H20: ='09. Administrativos '!$J$17 -> 0 | I20: ='09. Administrativos '!$K$17 -> 0 | J20: ='09. Administrativos '!$L$17 -> 0 | K20: ='09. Administrativos '!$M$17 -> 0 | L20: ='09. Administrativos '!$N$17 -> 0 | M20: ='09. Administrativos '!$O$17 -> 0 | N20: ='09. Administrativos '!$P$17 -> 168000000 | O20: =N20+(D20+E20+F20+G20+H20+I20+J20+K20+L20+M20) -> 168000000
B21: 10 | C21: Seguimiento | D21: ='10. Seguimiento'!$E$13 -> 0 | E21: ='10. Seguimiento'!$F$13 -> 0 | F21: ='10. Seguimiento'!$G$13 -> 0 | G21: ='10. Seguimiento'!$H$13 -> 0 | H21: ='10. Seguimiento'!$I$13 -> 0 | I21: ='10. Seguimiento'!$J$13 -> 0 | J21: ='10. Seguimiento'!$K$13 -> 0 | K21: ='10. Seguimiento'!$L$13 -> 0 | L21: ='10. Seguimiento'!$M$13 -> 0 | M21: ='10. Seguimiento'!$N$13 -> 0 | N21: ='10. Seguimiento'!$O$13 -> 192000000 | O21: =N21+(D21+E21+F21+G21+H21+I21+J21+K21+L21+M21) -> 192000000
B22: 11 | C22: Otros | D22: ='11. Otros'!$H$13 -> 0 | E22: ='11. Otros'!$I$13 -> 0 | F22: ='11. Otros'!$J$13 -> 0 | G22: ='11. Otros'!$K$13 -> 0 | H22: ='11. Otros'!$L$13 -> 0 | I22: ='11. Otros'!$M$13 -> 0 | J22: ='11. Otros'!$N$13 -> 0 | K22: ='11. Otros'!$O$13 -> 0 | L22: ='11. Otros'!$P$13 -> 0 | M22: ='11. Otros'!$Q$13 -> 0 | N22: ='11. Otros'!$R$13 -> 0 | O22: =N22+(D22+E22+F22+G22+H22+I22+J22+K22+L22+M22) -> 0
B23: TOTAL | D23: =SUM(D12:D22) -> 1244000000 | E23: =SUM(E12:E22) -> 0 | F23: =SUM(F12:F22) -> 60000000 | G23: =SUM(G12:G22) -> 0 | H23: =SUM(H12:H22) -> 60000000 | I23: =SUM(I12:I22) -> 0 | J23: =SUM(J12:J22) -> 150000000 | K23: =SUM(K12:K22) -> 0 | ... O23: =SUM(O12:O22) -> 15773405215
B25: Para efectos de la presentación de proyectos en la convocatoria, se sugiere realizar el análisis de costos a partir de dos cotizaciones. Si bien en la etapa de convocatoria no se exige la presentación de las cotizaciones, deberán presentarse en la actividad validación de requisitos del SGR posterior a la publicación del listado definitivo de elegibles.
B26: Se sugiere incluir un valor para imprevistos asociado a cada uno de los rubros presupuestales (cuando aplique). Es necesario aclarar que para poder contemplar imprevistos estos deben encontrarse asociados al análisis de riesgos y su cálculo debe encontrarse soportado en el análisis de costos.
B27: A continuación, se presenta una descripción de los rubros contemplados en el marco de esta convocatoria. En las pestañas siguientes se solicita describir brevemente los gastos asociados a cada rubro con el fin de la revisión de la razonabilidad del presupuesto frente al alcance del proyecto. Tenga en cuenta que los términos de referencia podrán realizar algunas precisiones respecto de los rubros financiables.
B29: DESCRIPCIÓN DE LOS RUBROS
B30: 1. Talento humano: El rubro de talento humano se dispone para el registro del personal científico, de investigación y demás requerido para la correcta ejecución del proyecto. Justifique e indique el tiempo de dedicación del personal de acuerdo con las necesidades del proyecto.
B31: 2. Equipos y software: equipos y software requeridos para el desarrollo del proyecto. Su necesidad y cantidad deben justificarse.
B32: 3. Capacitación y eventos: Se deben indicar los eventos de capacitación que se requeririan en el marco del proyecto
B33: 4. Servicios tecnológicos: Contrataciones que se hacen para la prestación de servicios especializados y cuya necesidad esté suficientemente justificada, por ejemplo: ensayos, pruebas, análisis de laboratorio y caracterizaciones, etc. Estos no deben incluirse en los gastos de personal. Describa el servicio tecnológico y justifique su necesidad con relación al alcance del proyecto.
B34: 5. Materiales, Insumos y Documentación: Adquisición de materiales, insumos, bienes fungibles, documentación y demás elementos necesarios para el desarrollo de algunas actividades previstas.
B35: 6. Protección de conocimiento y Divulgación: Hace referencia a las actividades de protección y/o divulgación que se desea adelantar. Se debe a la necesidad y cantidad, que debe guardar relación con el alcance del proyecto.
B36: 7. Gastos de viaje: Se refiere a los gastos de transporte (terrestres, aéreos y marítimos) y viáticos relacionados con las actividades a desarrollar por parte del talento humano en el marco del proyecto, y que son estrictamente necesarios para su ejecución y la generación de productos y resultados. En este apartado deberá indicar el trayecto, y la justificación técnica de su necesidad y cantidad en el marco del alcance del proyecto.
B37: 8. Infraestructura: Indique el tipo de infraestructura requerida (adecuación o mejora) en el marco del proyecto.
... B51: La entidad ejecutora es la Universidad Santo Tomás de Colombia, sede Villavicencio: contrata, paga y supervisa todo el presupuesto del SGR; las demás entidades no reciben recursos del SGR directamente (TdR §3) y aportan su contrapartida. La columna «SGR» muestra el valor de los ítems que cada entidad ejecuta o lidera (columna «Entidad responsable» de la hoja FC1). La asignación es una PROPUESTA que cada entidad debe validar.
B52: N.º | C52: Entidad | D52: Rol en el proyecto | G52: Actividades a su cargo o en las que participa | L52: Contrapartida en especie | M52: Contrapartida en efectivo | N52: SGR de las actividades que lidera o apoya | O52: TOTAL a su cargo
B53: 1 | C53: Universidad Santo Tomás de Colombia, sede Villavicencio — entidad proponente y ejecutora | D53: Proponente y ejecutora. Contrata y paga el 100 % del SGR; lidera el OE1 y el OE2 (red, plataforma geoespacial y laboratorio de modelación) y la formación de custodios. | G53: Todos los ítems no asignados a otra entidad: red IoT, referencias, banco de calibración, plataforma, laboratorio, campañas, propiedad intelectual, administración y seguimiento. | L53: =D23 -> 1244000000 | M53: =E23 -> 0 | N53: =SUMIF('FC1. Perfil de pagos'!$AV$8:$AV$137,"E1",'FC1. Perfil de pagos'!$G$8:$G$137) -> 12652344424 | O53: =L53+M53+N53 -> 13896344424
B54: 2 | C54: Municipio de Manizales (Caldas) | D54: Lugar de ejecución; uso institucional del tablero y del protocolo; acceso a los sitios. | G54: TH-20 (Profesionales de gestión del riesgo y logística de acceso a ) | L54: =F23 -> 60000000 | M54: =G23 -> 0 | N54: =SUMIF('FC1. Perfil de pagos'!$AV$8:$AV$137,"E2",'FC1. Perfil de pagos'!$G$8:$G$137) -> 0 | O54: =L54+M54+N54 -> 60000000
B55: 3 | C55: Municipio de Calarcá (Quindío) | D55: Lugar de ejecución; uso institucional del tablero y del protocolo; acceso a los sitios. | G55: TH-21 (Profesionales de gestión del riesgo y logística de acceso a ) | L55: =H23 -> 60000000 | M55: =I23 -> 0 | N55: =SUMIF('FC1. Perfil de pagos'!$AV$8:$AV$137,"E3",'FC1. Perfil de pagos'!$G$8:$G$137) -> 0 | O55: =L55+M55+N55 -> 60000000
B56: 4 | C56: Avanciencia — oficina de transferencia de resultados de investigación (OTRI) [razón social y NIT por diligenciar] | D56: Ejecuta la apropiación social del conocimiento (talleres de co-diseño, jornadas, cartillas, publicaciones y sus desplazamientos), los convenios y la formación de custodios y la propiedad intelectual; aporta en especie la vigilancia tecnológica y la valoración. | G56: CA-01 (Formación y soporte a custodios por tramo); CA-02 (Alimentación de laboratorios ciudadanos); CA-03 (Logística de ferias y laboratorios de apropiación); CA-05 (Desplazamientos del equipo de apropiación social de Avancien); MA-04 (Kits de papelería para talleres de co-diseño); PD-01 (Cartillas impresas del índice y del protocolo de alerta); PD-02 (Asesoría jurídica en propiedad intelectual y libertad de ope); PD-04 (Registro ante la DNDA y asesoría de propiedad intelectual); PD-05 (Publicaciones de divulgación y eventos de socialización); PD-06 (Registro del software y de los datos del modelo predictivo a); TH-07 (Coordinación de apropiación social); TH-13 (Profesionales de apropiación social); TH-16 (Profesional de convenios y custodia); TH-22 (Horas de investigadores y del equipo de transferencia de Ava); VI-04 (Viaje internacional para divulgación científica) | L56: =J23 -> 150000000 | M56: =K23 -> 0 | N56: =SUMIF('FC1. Perfil de pagos'!$AV$8:$AV$137,"E4",'FC1. Perfil de pagos'!$G$8:$G$137) -> 1347060791 | O56: =L56+M56+N56 -> 1497060791
B57: 5 | C57: Gestión y Medio Ambiente — aliado tecnológico [razón social y NIT por diligenciar] | D57: Aliado tecnológico: equipos de monitoreo y apoyo técnico en el diagnóstico, la colocalización y la verificación; aporte en efectivo propuesto. | G57: EQ-13 (Equipos de monitoreo de calidad del aire y apoyo técnico de ); VI-05 (Logística y viáticos de los tramos 2 y 3 — aporte en efectiv) | L57: =L23 -> 110000000 | M57: =M23 -> 150000000 | N57: =SUMIF('FC1. Perfil de pagos'!$AV$8:$AV$137,"E5",'FC1. Perfil de pagos'!$G$8:$G$137) -> 0 | O57: =L57+M57+N57 -> 260000000
C58: Sin entidad asignada | D58: Ítems cuya «Entidad responsable» (FC1) está vacía: asígnela para que el cuadro cuadre con el SGR de RESUMEN | N58: =N23-SUM(N53:N57) -> 0 | O58: =N58 -> 0
...

Sheet 01. Talento Humano
J3: 1. TALENTO HUMANO
K6: FUENTES
K7: CONTRAPARTIDA | U7: SGR | V7: TOTAL
B8: 1. TALENTO HUMANO | K8: Entidad 1 – Universidad Santo Tomás de Colombia, sede Villavicencio — entidad proponente y ejecutora | M8: Entidad 2 – Municipio de Manizales (Caldas) | O8: Entidad 3 – Municipio de Calarcá (Quindío) | Q8: Entidad 4 – Avanciencia — oficina de transferencia de resultados de investigación (OTRI) [razón social y NIT por diligenciar] | S8: Entidad 5 – Gestión y Medio Ambiente — aliado tecnológico [razón social y NIT por diligenciar]
B9: CARGO ESPECIFICO | C9: AÑOS DE EXPERIENCIA | D9: OBJETIVOS Y ACTIVIDADES EN LOS QUE PARTICIPA | E9: FUNCIÓN | F9: JUSTIFICACIÓN | G9: CANT | H9: DEDICACIÓN (h/sem) | I9: SEMANAS | J9: TOTAL | K9: Especie | L9: Efectivo | M9: Especie | N9: Efectivo | O9: Especie | P9: Efectivo | Q9: Especie | R9: Efectivo | S9: Especie | T9: Efectivo | U9: Efectivo
B10: Jóvenes investigadores e innovadores — cohorte 1 (estudiantes de pregrado) | C10: No aplica: estudiante de pregrado (TdR §14.4) | D10: OE1. A1.1 Seleccionar los sitios y diseñar la colocalización; A1.2 Adquirir y caracterizar el lote 1 de nodos y las referencias; A1.3 Instalar el tramo 1, colocalizar y calibrar en el piloto; A1.4 Entrenar y validar el modelo de corrección y decidir en la compuerta C1; A1.5 Reentrenar y verificar por municipio el tramo 2 y decidir en la compuerta C2; A1.6 Verificar el desempeño final y ejecutar el ensayo independiente | E10: Apoyar la colocalización y el modelo de corrección y entregar 1 artículo y 1 producto de divulgación cada uno. | F10: Tabla 20.2, producto 5: tres jóvenes en los meses 1 a 12; TdR §14.4: $2.000.000 mensuales, 12 meses. Sin la cohorte no se cumple el mínimo de seis jóvenes (TdR §9) ni el producto 5 (tres artículos publicables). Formación requerida: estudiantes de pregrado con 70 % de créditos; experiencia: semillero de investigación; funciones: apoyar la colocalización y el modelo de corrección y entregar 1 artículo y 1 producto de divulgación cada uno. Valor: TdR §14.4 (valor fijado). | G10: 3 | H10: Beca-pasantía | I10: ='MC. Memoria de cálculo'!$K$7 -> 52 | J10: ='MC. Memoria de cálculo'!$J$7 -> 72000000 | K10: 0 | L10: 0 | M10: 0 | N10: 0 | O10: 0 | P10: 0 | Q10: 0 | R10: 0 | S10: 0 | T10: 0 | U10: =J10-(K10+L10+M10+N10+O10+P10+Q10+R10+S10+T10) -> 72000000 | V10: =U10+K10+L10+M10+N10+O10+P10+Q10+R10+S10+T10 -> 72000000
B11: Jóvenes investigadores e innovadores — cohorte 2 (estudiantes de pregrado) | C11: No aplica: estudiante de pregrado (TdR §14.4) | D11: OE1. A1.1 Seleccionar los sitios y diseñar la colocalización; A1.2 Adquirir y caracterizar el lote 1 de nodos y las referencias; A1.3 Instalar el tramo 1, colocalizar y calibrar en el piloto; A1.4 Entrenar y validar el modelo de corrección y decidir en la compuerta C1; A1.5 Reentrenar y verificar por municipio el tramo 2 y decidir en la compuerta C2; A1.6 Verificar el desempeño final y ejecutar el ensayo independiente | E11: Reentrenamiento por municipio y ensayo independiente | F11: Tabla 20.2, producto 5: tres jóvenes en los meses 13 a 24; TdR §14.4: $2.000.000 mensuales, 12 meses. Sin la cohorte 2 no hay seis jóvenes (TdR §9) y se pierde el apoyo a los tramos 2 y 3. Formación requerida: estudiantes de pregrado con 70 % de créditos; funciones: reentrenamiento por municipio y ensayo independiente; 1 artículo y 1 producto de divulgación cada uno. Valor: TdR §14.4 (valor fijado). | G11: 3 | H11: Beca-pasantía | I11: ='MC. Memoria de cálculo'!$K$8 -> 52 | J11: ='MC. Memoria de cálculo'!$J$8 -> 72000000 | K11: 0 | L11: 0 | M11: 0 | N11: 0 | O11: 0 | P11: 0 | Q11: 0 | R11: 0 | S11: 0 | T11: 0 | U11: =J11-(K11+L11+M11+N11+O11+P11+Q11+R11+S11+T11) -> 72000000 | V11: =U11+K11+L11+M11+N11+O11+P11+Q11+R11+S11+T11 -> 72000000
B12: Estudiantes de maestría en modalidad de investigación (sostenimiento) | C12: No aplica: estudiante de maestría (TdR §14.4) | D12: OE1. A1.1 Seleccionar los sitios y diseñar la colocalización; A1.2 Adquirir y caracterizar el lote 1 de nodos y las referencias; A1.3 Instalar el tramo 1, colocalizar y calibrar en el piloto; A1.4 Entrenar y validar el modelo de corrección y decidir en la compuerta C1; A1.5 Reentrenar y verificar por municipio el tramo 2 y decidir en la compuerta C2; A1.6 Verificar el desempeño final y ejecutar el ensayo independiente | E12: Trabajo de grado asociado al modelo de corrección | F12: Tabla 20.2, producto 3: 2 estudiantes durante los meses 1 a 24; TdR §14.4: $4.350.000 mensuales. Sin ellos no se cumple el mínimo de dos estudiantes de maestría (TdR §9) ni los 2 documentos de investigación del producto 2. Formación requerida: admitidos a maestría de investigación con registro calificado; funciones: trabajo de grado asociado al modelo de corrección; 1 producto TOP o A y 1 de divulgación cada uno. Valor: TdR §14.4 (valor fijado). | G12: 2 | H12: Beca-pasantía | I12: ='MC. Memoria de cálculo'!$K$9 -> 104 | J12: ='MC. Memoria de cálculo'!$J$9 -> 208800000 | K12: 0 | L12: 0 | M12: 0 | N12: 0 | O12: 0 | P12: 0 | Q12: 0 | R12: 0 | S12: 0 | T12: 0 | U12: =J12-(K12+L12+M12+N12+O12+P12+Q12+R12+S12+T12) -> 208800000 | V12: =U12+K12+L12+M12+N12+O12+P12+Q12+R12+S12+T12 -> 208800000
B13: Matrícula de maestría en modalidad de investigación | C13: No aplica: matrícula de maestría | D13: OE1. A1.1 Seleccionar los sitios y diseñar la colocalización; A1.2 Adquirir y caracterizar el lote 1 de nodos y las referencias; A1.3 Instalar el tramo 1, colocalizar y calibrar en el piloto; A1.4 Entrenar y validar el modelo de corrección y decidir en la compuerta C1; A1.5 Reentrenar y verificar por municipio el tramo 2 y decidir en la compuerta C2; A1.6 Verificar el desempeño final y ejecutar el ensayo independiente | E13: Matrícula de maestría en modalidad de investigación | F13: Tabla 30.3, P02b: 2 matrículas al tope de $48.000.000 por estudiante (TdR §14.4). Sin la matrícula el estudiante no mantiene la admisión que exige el TdR §9.2; se incumple el producto 3. Valor: TdR §14.4 (valor fijado). | G13: 2 | H13: 0 | I13: ='MC. Memoria de cálculo'!$K$10 -> 0 | J13: ='MC. Memoria de cálculo'!$J$10 -> 96000000 | K13: 0 | L13: 0 | M13: 0 | N13: 0 | O13: 0 | P13: 0 | Q13: 0 | R13: 0 | S13: 0 | T13: 0 | U13: =J13-(K13+L13+M13+N13+O13+P13+Q13+R13+S13+T13) -> 96000000 | V13: =U13+K13+L13+M13+N13+O13+P13+Q13+R13+S13+T13 -> 96000000
B14: Doctor en estancia posdoctoral | C14: Doctor graduado (TdR §14.4) | D14: OE1. A1.1 Seleccionar los sitios y diseñar la colocalización; A1.2 Adquirir y caracterizar el lote 1 de nodos y las referencias; A1.3 Instalar el tramo 1, colocalizar y calibrar en el piloto; A1.4 Entrenar y validar el modelo de corrección y decidir en la compuerta C1; A1.5 Reentrenar y verificar por municipio el tramo 2 y decidir en la compuerta C2; A1.6 Verificar el desempeño final y ejecutar el ensayo independiente | E14: Asesorar a jóvenes y maestrantes | F14: Tabla 20.2, producto 4: 1 doctor durante los meses 1 a 24; TdR §14.4: $12.920.000 mensuales. Sin el posdoctor no se cumple el mínimo del TdR §9.3 ni se asesora a los 8 becarios. Formación requerida: doctorado; funciones: asesorar a jóvenes y maestrantes; 1 producto TOP o A, 1 de divulgación y 1 informe técnico final. Valor: TdR §14.4 (valor fijado). | G14: 1 | H14: Beca-pasantía | I14: ='MC. Memoria de cálculo'!$K$11 -> 104 | J14: ='MC. Memoria de cálculo'!$J$11 -> 310080000 | K14: 0 | L14: 0 | M14: 0 | N14: 0 | O14: 0 | P14: 0 | Q14: 0 | R14: 0 | S14: 0 | T14: 0 | U14: =J14-(K14+L14+M14+N14+O14+P14+Q14+R14+S14+T14) -> 310080000 | V14: =U14+K14+L14+M14+N14+O14+P14+Q14+R14+S14+T14 -> 310080000
B15: Ingenieros IoT y de campo | C15: Entre 5 y 10 años | D15: OE2. A2.1 Diseñar la arquitectura de enlace y energía; A2.2 Desarrollar el firmware y la plataforma base (gemelo digital y tablero); A2.3 Instalar el tramo 2; A2.4 Instalar el tramo 3 | E15: Diseñar el enlace y la energía de cada sitio e instalar, configurar y mantener nodos y gateways en 110 sitios | F15: Tabla 30.3, P04: 3 × 24 persona-mes. Sin este perfil la actividad 2.1–2.4 no se ejecuta con el responsable previsto; el producto P6 queda sin autor. Formación requerida: profesional en ingeniería electrónica, de telecomunicaciones o afín. Valor: Escala de honorarios de referencia (coeficientes de la Res. 426 de 2014 × SMLV 2026) + IPC 2025 en el año 2. | G15: 3 | H15: 40 | I15: ='MC. Memoria de cálculo'!$K$12 -> 104 | J15: ='MC. Memoria de cálculo'!$J$12 -> 743358993 | K15: 0 | L15: 0 | M15: 0 | N15: 0 | O15: 0 | P15: 0 | Q15: 0 | R15: 0 | S15: 0 | T15: 0 | U15: =J15-(K15+L15+M15+N15+O15+P15+Q15+R15+S15+T15) -> 743358993 | V15: =U15+K15+L15+M15+N15+O15+P15+Q15+R15+S15+T15 -> 743358993
B16: Coordinación de apropiación social | C16: Entre 1 y 5 años | D16: OE3. A3.1 Co-diseñar los umbrales y el protocolo de alerta con los consejos; A3.2 Poner en uso el tablero con los consejos; A3.3 Formar custodios y firmar los convenios por tramo; A3.4 Transferir, cerrar y evaluar | E16: Coordinar los 20 talleres de co-diseño y las 9 jornadas públicas | F16: Tabla 30.3, P05: 1 × 24 persona-mes. Sin este perfil la actividad 3.1–3.4 no se ejecuta con el responsable previsto; el producto P8 queda sin autor. Formación requerida: profesional en ciencias sociales, comunicación o gestión del riesgo. Valor: Escala de honorarios de referencia (coeficientes de la Res. 426 de 2014 × SMLV 2026) + IPC 2025 en el año 2. | G16: 1 | H16: 40 | I16: ='MC. Memoria de cálculo'!$K$13 -> 104 | J16: ='MC. Memoria de cálculo'!$J$13 -> 172373095 | K16: 0 | L16: 0 | M16: 0 | N16: 0 | O16: 0 | P16: 0 | Q16: 0 | R16: 0 | S16: 0 | T16: 0 | U16: =J16-(K16+L16+M16+N16+O16+P16+Q16+R16+S16+T16) -> 172373095 | V16: =U16+K16+L16+M16+N16+O16+P16+Q16+R16+S16+T16 -> 172373095
B17: Gerencia de proyecto | C17: Entre 5 y 10 años | D17: OE1, OE2 y OE3. A1.8 Administración y apoyo a la supervisión (objetivo específico 1); A2.8 Administración y apoyo a la supervisión (objetivo específico 2); A3.6 Administración y apoyo a la supervisión (objetivo específico 3) | E17: Responder por la ejecución, el cronograma y las compuertas C1 a C3 | F17: Tabla 30.3, P06: 1 × 24 persona-mes. Sin este perfil la actividad 1.8–3.6 no se ejecuta con el responsable previsto; el producto P1 queda sin autor. Formación requerida: profesional con especialización en gerencia de proyectos. Valor: Escala de honorarios de referencia (coeficientes de la Res. 426 de 2014 × SMLV 2026) + IPC 2025 en el año 2. | G17: 1 | H17: 40 | I17: ='MC. Memoria de cálculo'!$K$14 -> 104 | J17: ='MC. Memoria de cálculo'!$J$14 -> 247786331 | K17: 0 | L17: 0 | M17: 0 | N17: 0 | O17: 0 | P17: 0 | Q17: 0 | R17: 0 | S17: 0 | T17: 0 | U17: =J17-(K17+L17+M17+N17+O17+P17+Q17+R17+S17+T17) -> 247786331 | V17: =U17+K17+L17+M17+N17+O17+P17+Q17+R17+S17+T17 -> 247786331
B18: Especialista en metrología y calibración | C18: Entre 10 y 15 años | D18: OE1. A1.1 Seleccionar los sitios y diseñar la colocalización; A1.2 Adquirir y caracterizar el lote 1 de nodos y las referencias; A1.3 Instalar el tramo 1, colocalizar y calibrar en el piloto; A1.4 Entrenar y validar el modelo de corrección y decidir en la compuerta C1; A1.5 Reentrenar y verificar por municipio el tramo 2 y decidir en la compuerta C2; A1.6 Verificar el desempeño final y ejecutar el ensayo independiente | E18: Caracterizar los nodos frente a los 3 monitores de referencia y al banco de calibración | F18: Tabla 30.3, P07: 1 × 24 persona-mes. Sin este perfil la actividad 1.1–1.6 no se ejecuta con el responsable previsto; el producto P1 queda sin autor. Formación requerida: profesional en física o ingeniería. Valor: Escala de honorarios de referencia (coeficientes de la Res. 426 de 2014 × SMLV 2026) + IPC 2025 en el año 2. | G18: 1 | H18: 40 | I18: ='MC. Memoria de cálculo'!$K$15 -> 104 | J18: ='MC. Memoria de cálculo'!$J$15 -> 280106292 | K18: 0 | L18: 0 | M18: 0 | N18: 0 | O18: 0 | P18: 0 | Q18: 0 | R18: 0 | S18: 0 | T18: 0 | U18: =J18-(K18+L18+M18+N18+O18+P18+Q18+R18+S18+T18) -> 280106292 | V18: =U18+K18+L18+M18+N18+O18+P18+Q18+R18+S18+T18 -> 280106292
B19: Ingenieros de software y nube | C19: Entre 5 y 10 años | D19: OE2. A2.1 Diseñar la arquitectura de enlace y energía; A2.2 Desarrollar el firmware y la plataforma base (gemelo digital y tablero); A2.3 Instalar el tramo 2; A2.4 Instalar el tramo 3 | E19: Desarrollar la plataforma base, el gemelo digital y el tablero | F19: Tabla 30.3, P08: 2 × 24 persona-mes. Sin este perfil la actividad 2.1–2.4 no se ejecuta con el responsable previsto; el producto P6 queda sin autor. Formación requerida: profesional en ingeniería de sistemas o afín. Valor: Escala de honorarios de referencia (coeficientes de la Res. 426 de 2014 × SMLV 2026) + IPC 2025 en el año 2. | G19: 2 | H19: 40 | I19: ='MC. Memoria de cálculo'!$K$16 -> 104 | J19: ='MC. Memoria de cálculo'!$J$16 -> 495572662 | K19: 0 | L19: 0 | M19: 0 | N19: 0 | O19: 0 | P19: 0 | Q19: 0 | R19: 0 | S19: 0 | T19: 0 | U19: =J19-(K19+L19+M19+N19+O19+P19+Q19+R19+S19+T19) -> 495572662 | V19: =U19+K19+L19+M19+N19+O19+P19+Q19+R19+S19+T19 -> 495572662
B20: Ingeniero de firmware y energía | C20: Entre 5 y 10 años | D20: OE2. A2.1 Diseñar la arquitectura de enlace y energía; A2.2 Desarrollar el firmware y la plataforma base (gemelo digital y tablero); A2.3 Instalar el tramo 2; A2.4 Instalar el tramo 3 | E20: Desarrollar el firmware del nodo y dimensionar la autonomía de 14 días | F20: Tabla 30.3, P09: 1 × 24 persona-mes. Sin este perfil la actividad 2.1–2.4 no se ejecuta con el responsable previsto; el producto P6 queda sin autor. Formación requerida: profesional en ingeniería electrónica o mecatrónica. Valor: Escala de honorarios de referencia (coeficientes de la Res. 426 de 2014 × SMLV 2026) + IPC 2025 en el año 2. | G20: 1 | H20: 40 | I20: ='MC. Memoria de cálculo'!$K$17 -> 104 | J20: ='MC. Memoria de cálculo'!$J$17 -> 247786331 | K20: 0 | L20: 0 | M20: 0 | N20: 0 | O20: 0 | P20: 0 | Q20: 0 | R20: 0 | S20: 0 | T20: 0 | U20: =J20-(K20+L20+M20+N20+O20+P20+Q20+R20+S20+T20) -> 247786331 | V20: =U20+K20+L20+M20+N20+O20+P20+Q20+R20+S20+T20 -> 247786331
B21: Técnicos de campo municipales | C21: Entre 1 y 5 años | D21: OE2. A2.1 Diseñar la arquitectura de enlace y energía; A2.2 Desarrollar el firmware y la plataforma base (gemelo digital y tablero); A2.3 Instalar el tramo 2; A2.4 Instalar el tramo 3 | E21: Instalar y mantener los 110 sitios, tres técnicos por municipio | F21: Tabla 30.3, P10: 6 × 24 persona-mes. Sin este perfil la actividad 2.1–2.4 no se ejecuta con el responsable previsto; el producto P6 queda sin autor. Formación requerida: técnico en electrónica, telecomunicaciones o energías. Valor: Escala de honorarios de referencia (coeficientes de la Res. 426 de 2014 × SMLV 2026) + IPC 2025 en el año 2. | G21: 6 | H21: 40 | I21: ='MC. Memoria de cálculo'!$K$18 -> 104 | J21: ='MC. Memoria de cálculo'!$J$18 -> 646399182 | K21: 0 | L21: 0 | M21: 0 | N21: 0 | O21: 0 | P21: 0 | Q21: 0 | R21: 0 | S21: 0 | T21: 0 | U21: =J21-(K21+L21+M21+N21+O21+P21+Q21+R21+S21+T21) -> 646399182 | V21: =U21+K21+L21+M21+N21+O21+P21+Q21+R21+S21+T21 -> 646399182
B22: Profesionales de apropiación social | C22: Entre 1 y 5 años | D22: OE3. A3.1 Co-diseñar los umbrales y el protocolo de alerta con los consejos; A3.2 Poner en uso el tablero con los consejos; A3.3 Formar custodios y firmar los convenios por tramo; A3.4 Transferir, cerrar y evaluar | E22: Co-diseñar umbrales y formar a los custodios | F22: Tabla 30.3, P11: 2 × 24 persona-mes. Sin este perfil la actividad 3.1–3.4 no se ejecuta con el responsable previsto; el producto P8 queda sin autor. Formación requerida: profesional en ciencias sociales o ambientales. Valor: Escala de honorarios de referencia (coeficientes de la Res. 426 de 2014 × SMLV 2026) + IPC 2025 en el año 2. | G22: 2 | H22: 40 | I22: ='MC. Memoria de cálculo'!$K$19 -> 104 | J22: ='MC. Memoria de cálculo'!$J$19 -> 344746191 | K22: 0 | L22: 0 | M22: 0 | N22: 0 | O22: 0 | P22: 0 | Q22: 0 | R22: 0 | S22: 0 | T22: 0 | U22: =J22-(K22+L22+M22+N22+O22+P22+Q22+R22+S22+T22) -> 344746191 | V22: =U22+K22+L22+M22+N22+O22+P22+Q22+R22+S22+T22 -> 344746191
B23: Analista de datos espaciales y gemelo digital | C23: Entre 5 y 10 años | D23: OE2. A2.1 Diseñar la arquitectura de enlace y energía; A2.2 Desarrollar el firmware y la plataforma base (gemelo digital y tablero); A2.3 Instalar el tramo 2; A2.4 Instalar el tramo 3 | E23: Integrar datos geoespaciales y calibrar el gemelo digital | F23: Tabla 30.3, P12: 1 × 24 persona-mes. Sin este perfil la actividad 2.1–2.4 no se ejecuta con el responsable previsto; el producto P1 queda sin autor. Formación requerida: profesional en ingeniería, geomática o estadística. Valor: Escala de honorarios de referencia (coeficientes de la Res. 426 de 2014 × SMLV 2026) + IPC 2025 en el año 2. | G23: 1 | H23: 40 | I23: ='MC. Memoria de cálculo'!$K$20 -> 104 | J23: ='MC. Memoria de cálculo'!$J$20 -> 247786331 | K23: 0 | L23: 0 | M23: 0 | N23: 0 | O23: 0 | P23: 0 | Q23: 0 | R23: 0 | S23: 0 | T23: 0 | U23: =J23-(K23+L23+M23+N23+O23+P23+Q23+R23+S23+T23) -> 247786331 | V23: =U23+K23+L23+M23+N23+O23+P23+Q23+R23+S23+T23 -> 247786331
B24: Profesional en calidad del aire y salud ambiental | C24: Entre 5 y 10 años | D24: OE3. A3.1 Co-diseñar los umbrales y el protocolo de alerta con los consejos; A3.2 Poner en uso el tablero con los consejos; A3.3 Formar custodios y firmar los convenios por tramo; A3.4 Transferir, cerrar y evaluar | E24: Definir los umbrales del índice local de calidad del aire con los consejos de gestión del riesgo | F24: Tabla 30.3, P13: 1 × 24 persona-mes. Sin este perfil la actividad 3.1–3.4 no se ejecuta con el responsable previsto; el producto P7 queda sin autor. Formación requerida: profesional en ingeniería ambiental, química o salud pública. Valor: Escala de honorarios de referencia (coeficientes de la Res. 426 de 2014 × SMLV 2026) + IPC 2025 en el año 2. | G24: 1 | H24: 40 | I24: ='MC. Memoria de cálculo'!$K$21 -> 104 | J24: ='MC. Memoria de cálculo'!$J$21 -> 247786331 | K24: 0 | L24: 0 | M24: 0 | N24: 0 | O24: 0 | P24: 0 | Q24: 0 | R24: 0 | S24: 0 | T24: 0 | U24: =J24-(K24+L24+M24+N24+O24+P24+Q24+R24+S24+T24) -> 247786331 | V24: =U24+K24+L24+M24+N24+O24+P24+Q24+R24+S24+T24 -> 247786331
B25: Profesional de convenios y custodia | C25: Entre 1 y 5 años | D25: OE3. A3.1 Co-diseñar los umbrales y el protocolo de alerta con los consejos; A3.2 Poner en uso el tablero con los consejos; A3.3 Formar custodios y firmar los convenios por tramo; A3.4 Transferir, cerrar y evaluar | E25: Estructurar los convenios de custodia por tramo | F25: Tabla 30.3, P14: 1 × 24 persona-mes. Sin este perfil la actividad 3.1–3.4 no se ejecuta con el responsable previsto; el producto P7 queda sin autor. Formación requerida: profesional en derecho, administración o gestión pública. Valor: Escala de honorarios de referencia (coeficientes de la Res. 426 de 2014 × SMLV 2026) + IPC 2025 en el año 2. | G25: 1 | H25: 40 | I25: ='MC. Memoria de cálculo'!$K$22 -> 104 | J25: ='MC. Memoria de cálculo'!$J$22 -> 172373095 | K25: 0 | L25: 0 | M25: 0 | N25: 0 | O25: 0 | P25: 0 | Q25: 0 | R25: 0 | S25: 0 | T25: 0 | U25: =J25-(K25+L25+M25+N25+O25+P25+Q25+R25+S25+T25) -> 172373095 | V25: =U25+K25+L25+M25+N25+O25+P25+Q25+R25+S25+T25 -> 172373095
B26: Investigador líder en modelación atmosférica y dispersión de contaminantes | C26: Mayor a 15 años | D26: OE1, OE2 y OE3. A2.5 Diseñar el laboratorio de modelación y el inventario de emisión de demolición; A2.6 Dotar el laboratorio y montar la cadena de modelación; A2.7 Construir y calibrar el gemelo predictivo de demolición; A1.7 Validar el gemelo predictivo con demoliciones y remociones reales en los dos municipios; A3.5 Adoptar el protocolo de evaluación previa de demolición y transferir el laboratorio | E26: Diseñar la cadena de modelación, dirigir la construcción y calibración del gemelo predictivo de demolición y su validación con campañas reales | F26: Tabla 30.3, P15: 1 × 22 persona-mes. Sin este perfil la actividad 2.5–3.5 no se ejecuta con el responsable previsto; el producto P1 queda sin autor. Formación requerida: profesional con formación avanzada (maestría o doctorado recomendados) en física atmosférica, ingeniería ambiental o afín. Valor: Escala de honorarios de referencia (coeficientes de la Res. 426 de 2014 × SMLV 2026) + IPC 2025 en el año 2. | G26: 1 | H26: 40 | I26: ='MC. Memoria de cálculo'!$K$23 -> 95 | J26: ='MC. Memoria de cálculo'!$J$23 -> 296935990 | K26: 0 | L26: 0 | M26: 0 | N26: 0 | O26: 0 | P26: 0 | Q26: 0 | R26: 0 | S26: 0 | T26: 0 | U26: =J26-(K26+L26+M26+N26+O26+P26+Q26+R26+S26+T26) -> 296935990 | V26: =U26+K26+L26+M26+N26+O26+P26+Q26+R26+S26+T26 -> 296935990
B27: Ingeniero en dinámica de fluidos computacional y cómputo de alto rendimiento | C27: Entre 5 y 10 años | D27: OE1 y OE2. A2.6 Dotar el laboratorio y montar la cadena de modelación; A2.7 Construir y calibrar el gemelo predictivo de demolición; A1.7 Validar el gemelo predictivo con demoliciones y remociones reales en los dos municipios | E27: Montar y operar el servidor de cálculo, ejecutar las simulaciones de dispersión y asimilar los datos de las campañas | F27: Tabla 30.3, P16: 1 × 20 persona-mes. Sin este perfil la actividad 2.6–1.7 no se ejecuta con el responsable previsto; el producto P1 queda sin autor. Formación requerida: profesional en ingeniería mecánica, civil, aeroespacial o afín (posgrado recomendado). Valor: Escala de honorarios de referencia (coeficientes de la Res. 426 de 2014 × SMLV 2026) + IPC 2025 en el año 2. | G27: 1 | H27: 40 | I27: ='MC. Memoria de cálculo'!$K$24 -> 87 | J27: ='MC. Memoria de cálculo'!$J$24 -> 207515515 | K27: 0 | L27: 0 | M27: 0 | N27: 0 | O27: 0 | P27: 0 | Q27: 0 | R27: 0 | S27: 0 | T27: 0 | U27: =J27-(K27+L27+M27+N27+O27+P27+Q27+R27+S27+T27) -> 207515515 | V27: =U27+K27+L27+M27+N27+O27+P27+Q27+R27+S27+T27 -> 207515515
B28: Ingeniero en demolición y control de polvo en obra | C28: Entre 5 y 10 años | D28: OE1, OE2 y OE3. A2.5 Diseñar el laboratorio de modelación y el inventario de emisión de demolición; A1.7 Validar el gemelo predictivo con demoliciones y remociones reales en los dos municipios; A3.5 Adoptar el protocolo de evaluación previa de demolición y transferir el laboratorio | E28: Construir el inventario de emisión de demolición, coordinar el acceso a las campañas y los talleres de evaluación previa | F28: Tabla 30.3, P17: 1 × 14 persona-mes. Sin este perfil la actividad 2.5–3.5 no se ejecuta con el responsable previsto; el producto P1 queda sin autor. Formación requerida: profesional en ingeniería civil o afín. Valor: Escala de honorarios de referencia (coeficientes de la Res. 426 de 2014 × SMLV 2026) + IPC 2025 en el año 2. | G28: 1 | H28: 40 | I28: ='MC. Memoria de cálculo'!$K$25 -> 61 | J28: ='MC. Memoria de cálculo'!$J$25 -> 147109291 | K28: 0 | L28: 0 | M28: 0 | N28: 0 | O28: 0 | P28: 0 | Q28: 0 | R28: 0 | S28: 0 | T28: 0 | U28: =J28-(K28+L28+M28+N28+O28+P28+Q28+R28+S28+T28) -> 147109291 | V28: =U28+K28+L28+M28+N28+O28+P28+Q28+R28+S28+T28 -> 147109291
B29: Investigador principal (50 % durante 24 meses) — aporte de la entidad proponente | C29: Según certificación de la entidad aportante | D29: OE1, OE2 y OE3. A1.8 Administración y apoyo a la supervisión (objetivo específico 1); A2.8 Administración y apoyo a la supervisión (objetivo específico 2); A3.6 Administración y apoyo a la supervisión (objetivo específico 3) | E29: Investigador principal (50 % durante 24 meses) — aporte de la entidad proponente | F29: Tabla 28.7, C01: 50 % de dedicación durante 24 meses, valorado en $350.000.000. Sin su dirección científica el proyecto pierde al responsable de las compuertas C1–C3. Valor: Anexo 2, Tabla 28.7: aporte valorado en $350.000.000; certificación del representante legal pendiente. | G29: 1 | H29: 0 | I29: ='MC. Memoria de cálculo'!$K$26 -> 104 | J29: ='MC. Memoria de cálculo'!$J$26 -> 350000000 | K29: 350000000 | L29: 0 | M29: 0 | N29: 0 | O29: 0 | P29: 0 | Q29: 0 | R29: 0 | S29: 0 | T29: 0 | U29: =J29-(K29+L29+M29+N29+O29+P29+Q29+R29+S29+T29) -> 0 | V29: =U29+K29+L29+M29+N29+O29+P29+Q29+R29+S29+T29 -> 350000000
B30: Coinvestigador técnico (30 % durante 24 meses) — aporte de la entidad proponente | C30: Según certificación de la entidad aportante | D30: OE1. A1.1 Seleccionar los sitios y diseñar la colocalización; A1.2 Adquirir y caracterizar el lote 1 de nodos y las referencias; A1.3 Instalar el tramo 1, colocalizar y calibrar en el piloto; A1.4 Entrenar y validar el modelo de corrección y decidir en la compuerta C1; A1.5 Reentrenar y verificar por municipio el tramo 2 y decidir en la compuerta C2; A1.6 Verificar el desempeño final y ejecutar el ensayo independiente | E30: Coinvestigador técnico (30 % durante 24 meses) — aporte de la entidad proponente | F30: Tabla 28.7, C02: 30 % de dedicación durante 24 meses, valorado en $250.000.000. Sin este aporte la universidad no cubre la supervisión técnica del modelo de corrección. Valor: Anexo 2, Tabla 28.7: aporte valorado en $250.000.000; certificación del representante legal pendiente. | G30: 1 | H30: 0 | I30: ='MC. Memoria de cálculo'!$K$27 -> 104 | J30: ='MC. Memoria de cálculo'!$J$27 -> 250000000 | K30: 250000000 | L30: 0 | M30: 0 | N30: 0 | O30: 0 | P30: 0 | Q30: 0 | R30: 0 | S30: 0 | T30: 0 | U30: =J30-(K30+L30+M30+N30+O30+P30+Q30+R30+S30+T30) -> 0 | V30: =U30+K30+L30+M30+N30+O30+P30+Q30+R30+S30+T30 -> 250000000
B31: Coinvestigadores de ambiente y ciencias sociales (20 %) — aporte de la entidad proponente | C31: Según certificación de la entidad aportante | D31: OE3. A3.1 Co-diseñar los umbrales y el protocolo de alerta con los consejos; A3.2 Poner en uso el tablero con los consejos; A3.3 Formar custodios y firmar los convenios por tramo; A3.4 Transferir, cerrar y evaluar | E31: Coinvestigadores de ambiente y ciencias sociales (20 %) — aporte de la entidad proponente | F31: Tabla 28.7, C03: 20 % de dedicación, valorado en $200.000.000. Sin ellos el co-diseño con los 4 consejos de gestión del riesgo queda sin respaldo metodológico. Valor: Anexo 2, Tabla 28.7: aporte valorado en $200.000.000; certificación del representante legal pendiente. | G31: 1 | H31: 0 | I31: ='MC. Memoria de cálculo'!$K$28 -> 95 | J31: ='MC. Memoria de cálculo'!$J$28 -> 200000000 | K31: 200000000 | L31: 0 | M31: 0 | N31: 0 | O31: 0 | P31: 0 | Q31: 0 | R31: 0 | S31: 0 | T31: 0 | U31: =J31-(K31+L31+M31+N31+O31+P31+Q31+R31+S31+T31) -> 0 | V31: =U31+K31+L31+M31+N31+O31+P31+Q31+R31+S31+T31 -> 200000000
B32: Profesionales de gestión del riesgo y logística de acceso a sitios — aporte del municipio 1 | C32: Según certificación de la entidad aportante | D32: OE3. A3.1 Co-diseñar los umbrales y el protocolo de alerta con los consejos; A3.2 Poner en uso el tablero con los consejos; A3.3 Formar custodios y firmar los convenios por tramo; A3.4 Transferir, cerrar y evaluar | E32: Profesionales de gestión del riesgo y logística de acceso a sitios — aporte del municipio 1 | F32: Tabla 28.7, C07: aporte de los municipios valorado en $120.000.000, repartido por igual entre el municipio 1 y el municipio 2 (PROPUESTA; el Anexo 2 no separa personal y logística). Sin el municipio no hay acceso a los sitios de remoción ni convocatoria de los consejos de gestión del riesgo. Valor: Anexo 2, Tabla 28.7: aporte valorado en $60.000.000; certificación del representante legal pendiente. | G32: 1 | H32: 0 | I32: ='MC. Memoria de cálculo'!$K$29 -> 95 | J32: ='MC. Memoria de cálculo'!$J$29 -> 60000000 | K32: 0 | L32: 0 | M32: 60000000 | N32: 0 | O32: 0 | P32: 0 | Q32: 0 | R32: 0 | S32: 0 | T32: 0 | U32: =J32-(K32+L32+M32+N32+O32+P32+Q32+R32+S32+T32) -> 0 | V32: =U32+K32+L32+M32+N32+O32+P32+Q32+R32+S32+T32 -> 60000000
B33: Profesionales de gestión del riesgo y logística de acceso a sitios — aporte del municipio 2 | C33: Según certificación de la entidad aportante | D33: OE3. A3.1 Co-diseñar los umbrales y el protocolo de alerta con los consejos; A3.2 Poner en uso el tablero con los consejos; A3.3 Formar custodios y firmar los convenios por tramo; A3.4 Transferir, cerrar y evaluar | E33: Profesionales de gestión del riesgo y logística de acceso a sitios — aporte del municipio 2 | F33: Tabla 28.7, C07: la otra mitad del aporte de los municipios, $60.000.000 (reparto PROPUESTO entre los dos municipios). Sin el municipio 2 no hay acceso a sus sitios de remoción ni convocatoria de su comité. Valor: Anexo 2, Tabla 28.7: aporte valorado en $60.000.000; certificación del representante legal pendiente. | G33: 1 | H33: 0 | I33: ='MC. Memoria de cálculo'!$K$30 -> 95 | J33: ='MC. Memoria de cálculo'!$J$30 -> 60000000 | K33: 0 | L33: 0 | M33: 0 | N33: 0 | O33: 60000000 | P33: 0 | Q33: 0 | R33: 0 | S33: 0 | T33: 0 | U33: =J33-(K33+L33+M33+N33+O33+P33+Q33+R33+S33+T33) -> 0 | V33: =U33+K33+L33+M33+N33+O33+P33+Q33+R33+S33+T33 -> 60000000
B34: Horas de investigadores y del equipo de transferencia de Avanciencia (OTRI) — aporte en especie (PROPUESTA) | C34: Según certificación de la entidad aportante | D34: OE1 y OE3. A1.1 Seleccionar los sitios y diseñar la colocalización; A1.2 Adquirir y caracterizar el lote 1 de nodos y las referencias; A1.4 Entrenar y validar el modelo de corrección y decidir en la compuerta C1; A1.6 Verificar el desempeño final y ejecutar el ensayo independiente; A3.3 Formar custodios y firmar los convenios por tramo; A3.4 Transferir, cerrar y evaluar | E34: Horas de investigadores y del equipo de transferencia de Avanciencia (OTRI) — aporte en especie (PROPUESTA) | F34: Tabla 28.7, C08: el Anexo 2 deja el valor pendiente; el Anexo 3 propone $150.000.000 para que la OTRI cumpla la contrapartida exigida a cada integrante. Sin el aporte la OTRI no cumple la exigencia de contrapartida de cada integrante (TdR §3). Valor: Anexo 2, Tabla 28.7: aporte valorado en $150.000.000; certificación del representante legal pendiente. | G34: 1 | H34: 0 | I34: ='MC. Memoria de cálculo'!$K$31 -> 100 | J34: ='MC. Memoria de cálculo'!$J$31 -> 150000000 | K34: 0 | L34: 0 | M34: 0 | N34: 0 | O34: 0 | P34: 0 | Q34: 150000000 | R34: 0 | S34: 0 | T34: 0 | U34: =J34-(K34+L34+M34+N34+O34+P34+Q34+R34+S34+T34) -> 0 | V34: =U34+K34+L34+M34+N34+O34+P34+Q34+R34+S34+T34 -> 150000000
J35: 0 | K35: 0 | L35: 0 | M35: 0 | N35: 0 | O35: 0 | P35: 0 | Q35: 0 | R35: 0 | S35: 0 | T35: 0 | U35: =J35-(K35+L35+M35+N35+O35+P35+Q35+R35+S35+T35) -> 0 | V35: =U35+K35+L35+M35+N35+O35+P35+Q35+R35+S35+T35 -> 0
J36: 0 | K36: 0 | L36: 0 | M36: 0 | N36: 0 | O36: 0 | P36: 0 | Q36: 0 | R36: 0 | S36: 0 | T36: 0 | U36: =J36-(K36+L36+M36+N36+O36+P36+Q36+R36+S36+T36) -> 0 | V36: =U36+K36+L36+M36+N36+O36+P36+Q36+R36+S36+T36 -> 0
J37: 0 | K37: 0 | L37: 0 | M37: 0 | N37: 0 | O37: 0 | P37: 0 | Q37: 0 | R37: 0 | S37: 0 | T37: 0 | U37: =J37-(K37+L37+M37+N37+O37+P37+Q37+R37+S37+T37) -> 0 | V37: =U37+K37+L37+M37+N37+O37+P37+Q37+R37+S37+T37 -> 0
B38: TOTAL | J38: =SUM(J10:J37) -> 6326515630 | K38: =SUM(K10:K37) -> 800000000 | L38: =SUM(L10:L37) -> 0 | M38: =SUM(M10:M37) -> 60000000 | N38: =SUM(N10:N37) -> 0 | O38: =SUM(O10:O37) -> 60000000 | P38: =SUM(P10:P37) -> 0 | Q38: =SUM(Q10:Q37) -> 150000000 | ... V38: =SUM(V10:V37) -> 6326515630
B41: En caso de requerir valores base para calcular tarifas de honorarios, se recomienda tener en cuenta las tarifas establecidas por la región, mediante acto administrativo, por el cual se establecen los parámetros para determinar los honorarios de los contratos de Prestación de Servicios Profesionales y Apoyo a la Gestión en la vigencia Fiscal. • Para el cálculo de los honorarios del personal, se sugiere tener en cuenta el incremento anual a los topes establecidos, en el mismo porcentaje del índice de precios al consumidor (IPC) certificado por el DANE para el año calendario (1° de enero a 31 de diciembre) inmediatamente anterior a aquel en que deba aplicarse el reajuste. • Para efectos de cálculo, tenga en cuenta que un año se compone de 52 semanas. • Se espera que la dedicación de al menos un miembro del equipo investigador (Investigador Principal, Director de Proyecto, etc.) guarde relación con el tiempo total destinado para la ejecución total del proyecto. En la justificación debe considerar lo siguiente: -Nivel de formación académica: Indique el nivel de formación requerido por los participantes para el proyecto (bachiller / Técnico / Tecnólogo / Pregrado / Posgrado en la modalidad de: Especialización, Maestría, Doctorado o Posdoctorado). -Experiencia o conocimientos requeridos: indique la experiencia o conocimientos requeridos por los participantes para prestar los servicios profesionales conforme a las necesidades del proyecto. - Años de experiencia: indique el número de años de experiencia profesional requerida por los participantes para el proyecto, de acuerdo con las necesidades del mismo. - Funciones: especifique, de manera precisa y resumida, las funciones o actividades a desarrollar por cada uno de los participantes en el proyecto.

Sheet Proyección Financiera
C7: FORMATO DE PROYECCION FINANCIERA
C8: RECURSOS FONDO DE CTeI SGR
C9: Pesos Colombianos
C11: Nombre o Título del Programa o Proyecto: | D11: Implementación de una red IoT híbrida Edge-Cloud y gemelo digital para la gestión anticipada del riesgo por material particulado posterremoto
C12: Ejecutor: | D12: Universidad Santo Tomás de Colombia, sede Villavicencio (entidad proponente y ejecutora) [NIT y representante legal por diligenciar]
C13: Valor: | D13: ='RESUMEN'!$O$23 -> 15773405215
C14: Duración del Proyecto: | D14: 24 Meses
C15: Periodo de Ejecución: | D15: Mes 1 a Mes 24
B18: PROYECCIÓN FINANCIERA DETALLADA
B20: INGRESOS | D20: Periodo 0 – Año 1 ($) | E20: Periodo 1 – Año 2 ($) | F20: (sin período) | G20: TOTAL ($)
C22: Saldo inicial efectivo SGR | D22: 0 | E22: ='FC2. Flujo mensual'!N71 -> 0 | F22: 0 | G22: =D22 -> 0
C23: Contrapartida | D23: ='FC2. Flujo mensual'!AB51 -> 8.0981324e+08 | E23: ='FC2. Flujo mensual'!AC51 -> 9.6418676e+08 | F23: 0 | G23: =SUM(D23:F23) -> 1774000000
C24: Giro Sistema General de Regalías | D24: ='FC2. Flujo mensual'!AB58 -> 7.6207893e+09 | E24: ='FC2. Flujo mensual'!AC58 -> 6.378616e+09 | F24: 0 | G24: =SUM(D24:F24) -> 13999405215
B25: Total | D25: =SUM(D22:D24) -> 8.4306025e+09 | E25: =SUM(E22:E24) -> 7.3428027e+09 | F25: =SUM(F22:F24) -> 0 | G25: =SUM(G22:G24) -> 15773405215
B27: EGRESOS POR RUBROS
B28: 01. | C28: Talento humano | D28: ='FC2. Flujo mensual'!AB10 -> 3.0586638e+09 | E28: ='FC2. Flujo mensual'!AC10 -> 3.2678518e+09 | F28: 0 | G28: =SUM(D28:F28) -> 6326515630
B29: 02. | C29: Equipos y software | D29: ='FC2. Flujo mensual'!AB11 -> 4.05286e+09 | E29: ='FC2. Flujo mensual'!AC11 -> 1.9660257e+09 | F29: 0 | G29: =SUM(D29:F29) -> 6018885709
B30: 03. | C30: Capacitación y participación en eventos | D30: ='FC2. Flujo mensual'!AB12 -> 88705921 | E30: ='FC2. Flujo mensual'!AC12 -> 3.2826249e+08 | F30: 0 | G30: =SUM(D30:F30) -> 416968410
B31: 04. | C31: Servicios tecnológicos y pruebas | D31: ='FC2. Flujo mensual'!AB13 -> 5.635195e+08 | E31: ='FC2. Flujo mensual'!AC13 -> 8.3313175e+08 | F31: 0 | G31: =SUM(D31:F31) -> 1396651250
B32: 05. | C32: Materiales, insumos y documentación | D32: ='FC2. Flujo mensual'!AB14 -> 110496944 | E32: ='FC2. Flujo mensual'!AC14 -> 144657536 | F32: 0 | G32: =SUM(D32:F32) -> 255154480
B33: 06. | C33: Protección de conocimiento y divulgación | D33: ='FC2. Flujo mensual'!AB15 -> 1.1643761e+08 | E33: ='FC2. Flujo mensual'!AC15 -> 1.4351588e+08 | F33: 0 | G33: =SUM(D33:F33) -> 259953486
B34: 07. | C34: Gastos de viaje | D34: ='FC2. Flujo mensual'!AB16 -> 1.9391872e+08 | E34: ='FC2. Flujo mensual'!AC16 -> 4.1335753e+08 | F34: 0 | G34: =SUM(D34:F34) -> 607276250
B35: 08. | C35: Infraestructura | D35: ='FC2. Flujo mensual'!AB17 -> 66000000 | E35: ='FC2. Flujo mensual'!AC17 -> 66000000 | F35: 0 | G35: =SUM(D35:F35) -> 132000000
B36: 09. | C36: Administrativos | D36: ='FC2. Flujo mensual'!AB18 -> 84000000 | E36: ='FC2. Flujo mensual'!AC18 -> 84000000 | F36: 0 | G36: =SUM(D36:F36) -> 168000000
B37: 10. | C37: Seguimiento (interventoría o apoyo a la supervisión) | D37: ='FC2. Flujo mensual'!AB19 -> 96000000 | E37: ='FC2. Flujo mensual'!AC19 -> 96000000 | F37: 0 | G37: =SUM(D37:F37) -> 192000000
B38: 11. | C38: Otros | D38: ='FC2. Flujo mensual'!AB20 -> 0 | E38: ='FC2. Flujo mensual'!AC20 -> 0 | F38: 0 | G38: =SUM(D38:F38) -> 0
B39: TOTAL | D39: =SUM(D28:D38) -> 8.4306025e+09 | E39: =SUM(E28:E38) -> 7.3428027e+09 | F39: =SUM(F28:F38) -> 0 | G39: =SUM(G28:G38) -> 15773405215
B41: PROGRAMACIÓN DE DESEMBOLSOS SISTEMA GENERAL DE REGALIAS
B43: Desembolso | D43: Fecha Estimada de solicitud | G43: Periodo de Cobertura | H43: Meses de Cobertura | I43: Valor
I44: Giro Sistema General de Regalías
B45: 1 | D45: Mes 1 (Mes 1) | G45: 0 | H45: Mes 1 a 6 | I45: ='FC2. Flujo mensual'!C54 -> 4.8899452e+09
B46: 2 | D46: Mes 7 (Mes 7) | G46: 0 | H46: Mes 7 a 12 | I46: ='FC2. Flujo mensual'!I55 -> 2.730844e+09
B47: 3 | D47: Mes 13 (Mes 13) | G47: 1 | H47: Mes 13 a 18 | I47: ='FC2. Flujo mensual'!O56 -> 4.0120774e+09
B48: 4 | D48: Mes 19 (Mes 19) | G48: 1 | H48: Mes 19 a 24 | I48: ='FC2. Flujo mensual'!U57 -> 2.3665385e+09
B50: TOTAL | I50: =SUM(I45:I49) -> 13999405215

Sheet Cronograma financiero
A1: CRONOGRAMA FINANCIERO · Implementación de una red IoT híbrida Edge-Cloud y gemelo digital para la gestión anticipada del riesgo por material particulado posterremoto
A2: Objetivo específico | B2: Número actividad | C2: Actividad MGA | D2: Duración total de la actividad (meses) | E2: Rubro presupuestal asociado a la actividad | F2: Ítem del rubro | G2: Duración ejecución del ítem (meses) | H2: Mes inicio | I2: Mes fin | J2: Valor año 1 | K2: Valor año 2 | L2: Mes 1 | M2: Mes 2 | N2: Mes 3 | O2: Mes 4 | P2: Mes 5 | Q2: Mes 6 | R2: Mes 7 | S2: Mes 8 | T2: Mes 9 | U2: Mes 10 | V2: Mes 11 | W2: Mes 12 | X2: Año 1 Período 0 | Y2: Mes 13 | Z2: Mes 14 | AA2: Mes 15 | AB2: Mes 16 | AC2: Mes 17 | AD2: Mes 18 | AE2: Mes 19 | AF2: Mes 20 | AG2: Mes 21 | AH2: Mes 22 | AI2: Mes 23 | AJ2: Mes 24 | AK2: Año 2 Período 1 | AL2: Valor | AM2: Control
L3: Sem 1–4 | M3: Sem 5–8 | N3: Sem 9–13 | O3: Sem 14–17 | P3: Sem 18–21 | Q3: Sem 22–26 | R3: Sem 27–30 | S3: Sem 31–34 | T3: Sem 35–39 | U3: Sem 40–43 | V3: Sem 44–47 | W3: Sem 48–52 | Y3: Sem 53–56 | Z3: Sem 57–60 | AA3: Sem 61–65 | AB3: Sem 66–69 | AC3: Sem 70–73 | AD3: Sem 74–78 | AE3: Sem 79–82 | AF3: Sem 83–86 | AG3: Sem 87–91 | AH3: Sem 92–95 | AI3: Sem 96–99 | AJ3: Sem 100–104
A4: =IFERROR(INDEX($B$139:$B$160,MATCH($B4,$A$139:$A$160,0)),"") -> OE1 | B4: ='FC1. Perfil de pagos'!AQ8 -> A1.1 | C4: =IFERROR(INDEX($C$139:$C$160,MATCH($B4,$A$139:$A$160,0)),"") -> Seleccionar los sitios y diseñar la colocalización | D4: =IFERROR(INDEX($D$139:$D$160,MATCH($B4,$A$139:$A$160,0)),"") -> 2 | E4: Talento humano | F4: ='FC1. Perfil de pagos'!D8 -> Jóvenes investigadores e innovadores — cohorte 1 (estudiantes de pregrado) | G4: =I4-H4+1 -> 12 | H4: ='FC1. Perfil de pagos'!AR8 -> 1 | I4: ='FC1. Perfil de pagos'!AS8 -> 12 | J4: =X4 -> 72000000 | K4: =AK4 -> 0 | L4: ='FC1. Perfil de pagos'!H142 -> 6000000 | M4: ='FC1. Perfil de pagos'!I142 -> 6000000 | N4: ='FC1. Perfil de pagos'!J142 -> 6000000 | O4: ='FC1. Perfil de pagos'!K142 -> 6000000 | P4: ='FC1. Perfil de pagos'!L142 -> 6000000 | Q4: ='FC1. Perfil de pagos'!M142 -> 6000000 | R4: ='FC1. Perfil de pagos'!N142 -> 6000000 | S4: ='FC1. Perfil de pagos'!O142 -> 6000000 | ... W4: ='FC1. Perfil de pagos'!S142 -> 6000000 | X4: =SUM(L4:W4) -> 72000000 | Y4: ='FC1. Perfil de pagos'!T142 -> 0 | Z4: ='FC1. Perfil de pagos'!U142 -> 0 | AA4: ='FC1. Perfil de pagos'!V142 -> 0 | AB4: ='FC1. Perfil de pagos'!W142 -> 0 | AC4: ='FC1. Perfil de pagos'!X142 -> 0 | AD4: ='FC1. Perfil de pagos'!Y142 -> 0 | AE4: ='FC1. Perfil de pagos'!Z142 -> 0 | AF4: ='FC1. Perfil de pagos'!AA142 -> 0 | ... AJ4: ='FC1. Perfil de pagos'!AE142 -> 0 | AK4: =SUM(Y4:AJ4) -> 0 | AL4: =X4+AK4 -> 72000000 | AM4: =IF(ABS(AL4-'01. Talento Humano'!$J$10)<1,"OK","ERROR") -> OK
A5: =IFERROR(INDEX($B$139:$B$160,MATCH($B5,$A$139:$A$160,0)),"") -> OE1 | B5: ='FC1. Perfil de pagos'!AQ9 -> A1.1 | C5: =IFERROR(INDEX($C$139:$C$160,MATCH($B5,$A$139:$A$160,0)),"") -> Seleccionar los sitios y diseñar la colocalización | D5: =IFERROR(INDEX($D$139:$D$160,MATCH($B5,$A$139:$A$160,0)),"") -> 2 | E5: Talento humano | F5: ='FC1. Perfil de pagos'!D9 -> Jóvenes investigadores e innovadores — cohorte 2 (estudiantes de pregrado) | G5: =I5-H5+1 -> 12 | H5: ='FC1. Perfil de pagos'!AR9 -> 13 | I5: ='FC1. Perfil de pagos'!AS9 -> 24 | J5: =X5 -> 0 | K5: =AK5 -> 72000000 | L5: ='FC1. Perfil de pagos'!H143 -> 0 | M5: ='FC1. Perfil de pagos'!I143 -> 0 | N5: ='FC1. Perfil de pagos'!J143 -> 0 | O5: ='FC1. Perfil de pagos'!K143 -> 0 | P5: ='FC1. Perfil de pagos'!L143 -> 0 | Q5: ='FC1. Perfil de pagos'!M143 -> 0 | R5: ='FC1. Perfil de pagos'!N143 -> 0 | S5: ='FC1. Perfil de pagos'!O143 -> 0 | ... W5: ='FC1. Perfil de pagos'!S143 -> 0 | X5: =SUM(L5:W5) -> 0 | Y5: ='FC1. Perfil de pagos'!T143 -> 6000000 | Z5: ='FC1. Perfil de pagos'!U143 -> 6000000 | AA5: ='FC1. Perfil de pagos'!V143 -> 6000000 | AB5: ='FC1. Perfil de pagos'!W143 -> 6000000 | AC5: ='FC1. Perfil de pagos'!X143 -> 6000000 | AD5: ='FC1. Perfil de pagos'!Y143 -> 6000000 | AE5: ='FC1. Perfil de pagos'!Z143 -> 6000000 | AF5: ='FC1. Perfil de pagos'!AA143 -> 6000000 | ... AJ5: ='FC1. Perfil de pagos'!AE143 -> 6000000 | AK5: =SUM(Y5:AJ5) -> 72000000 | AL5: =X5+AK5 -> 72000000 | AM5: =IF(ABS(AL5-'01. Talento Humano'!$J$11)<1,"OK","ERROR") -> OK
A6: =IFERROR(INDEX($B$139:$B$160,MATCH($B6,$A$139:$A$160,0)),"") -> OE1 | B6: ='FC1. Perfil de pagos'!AQ10 -> A1.1 | C6: =IFERROR(INDEX($C$139:$C$160,MATCH($B6,$A$139:$A$160,0)),"") -> Seleccionar los sitios y diseñar la colocalización | D6: =IFERROR(INDEX($D$139:$D$160,MATCH($B6,$A$139:$A$160,0)),"") -> 2 | E6: Talento humano | F6: ='FC1. Perfil de pagos'!D10 -> Estudiantes de maestría en modalidad de investigación (sostenimiento) | G6: =I6-H6+1 -> 24 | H6: ='FC1. Perfil de pagos'!AR10 -> 1 | I6: ='FC1. Perfil de pagos'!AS10 -> 24 | J6: =X6 -> 104400000 | K6: =AK6 -> 104400000 | L6: ='FC1. Perfil de pagos'!H144 -> 8700000 | M6: ='FC1. Perfil de pagos'!I144 -> 8700000 | N6: ='FC1. Perfil de pagos'!J144 -> 8700000 | O6: ='FC1. Perfil de pagos'!K144 -> 8700000 | P6: ='FC1. Perfil de pagos'!L144 -> 8700000 | Q6: ='FC1. Perfil de pagos'!M144 -> 8700000 | R6: ='FC1. Perfil de pagos'!N144 -> 8700000 | S6: ='FC1. Perfil de pagos'!O144 -> 8700000 | ... W6: ='FC1. Perfil de pagos'!S144 -> 8700000 | X6: =SUM(L6:W6) -> 104400000 | Y6: ='FC1. Perfil de pagos'!T144 -> 8700000 | Z6: ='FC1. Perfil de pagos'!U144 -> 8700000 | AA6: ='FC1. Perfil de pagos'!V144 -> 8700000 | AB6: ='FC1. Perfil de pagos'!W144 -> 8700000 | AC6: ='FC1. Perfil de pagos'!X144 -> 8700000 | AD6: ='FC1. Perfil de pagos'!Y144 -> 8700000 | AE6: ='FC1. Perfil de pagos'!Z144 -> 8700000 | AF6: ='FC1. Perfil de pagos'!AA144 -> 8700000 | ... AJ6: ='FC1. Perfil de pagos'!AE144 -> 8700000 | AK6: =SUM(Y6:AJ6) -> 104400000 | AL6: =X6+AK6 -> 208800000 | AM6: =IF(ABS(AL6-'01. Talento Humano'!$J$12)<1,"OK","ERROR") -> OK
A7: =IFERROR(INDEX($B$139:$B$160,MATCH($B7,$A$139:$A$160,0)),"") -> OE1 | B7: ='FC1. Perfil de pagos'!AQ11 -> A1.1 | C7: =IFERROR(INDEX($C$139:$C$160,MATCH($B7,$A$139:$A$160,0)),"") -> Seleccionar los sitios y diseñar la colocalización | D7: =IFERROR(INDEX($D$139:$D$160,MATCH($B7,$A$139:$A$160,0)),"") -> 2 | E7: Talento humano | F7: ='FC1. Perfil de pagos'!D11 -> Matrícula de maestría en modalidad de investigación | G7: =I7-H7+1 -> 24 | H7: ='FC1. Perfil de pagos'!AR11 -> 1 | I7: ='FC1. Perfil de pagos'!AS11 -> 24 | J7: =X7 -> 48000000 | K7: =AK7 -> 48000000 | L7: ='FC1. Perfil de pagos'!H145 -> 24000000 | M7: ='FC1. Perfil de pagos'!I145 -> 0 | N7: ='FC1. Perfil de pagos'!J145 -> 0 | O7: ='FC1. Perfil de pagos'!K145 -> 0 | P7: ='FC1. Perfil de pagos'!L145 -> 0 | Q7: ='FC1. Perfil de pagos'!M145 -> 0 | R7: ='FC1. Perfil de pagos'!N145 -> 24000000 | S7: ='FC1. Perfil de pagos'!O145 -> 0 | ... W7: ='FC1. Perfil de pagos'!S145 -> 0 | X7: =SUM(L7:W7) -> 48000000 | Y7: ='FC1. Perfil de pagos'!T145 -> 24000000 | Z7: ='FC1. Perfil de pagos'!U145 -> 0 | AA7: ='FC1. Perfil de pagos'!V145 -> 0 | AB7: ='FC1. Perfil de pagos'!W145 -> 0 | AC7: ='FC1. Perfil de pagos'!X145 -> 0 | AD7: ='FC1. Perfil de pagos'!Y145 -> 0 | AE7: ='FC1. Perfil de pagos'!Z145 -> 24000000 | AF7: ='FC1. Perfil de pagos'!AA145 -> 0 | ... AJ7: ='FC1. Perfil de pagos'!AE145 -> 0 | AK7: =SUM(Y7:AJ7) -> 48000000 | AL7: =X7+AK7 -> 96000000 | AM7: =IF(ABS(AL7-'01. Talento Humano'!$J$13)<1,"OK","ERROR") -> OK
