Workbook
Name matrizOK: M!$C$6
Name nombreEstudio: M!$G$6
Name nVariables: M!$C$4

Sheet Resultados
A1: ="Resultados | De las relaciones directas a los recorridos de seis vínculos"&IF(nombreEstudio<>""," · "&nombreEstudio,"")
A2: Única entrada: hoja M (nombres y celdas azul claro). Todo lo demás se calcula solo. Primero comprenda una celda en Paso a paso; después compare M1 a M6 en Evolución. Los gráficos vectoriales (SVG) están en la hoja SVG.
A3: =IF(matrizOK,IF('M1'!$C$9=0,"M contiene solo ceros. No hay relaciones para clasificar.","M completa: "&nVariables&" variables. Los resultados siguientes proceden de sus valoraciones actuales."),"REVISE M: resultados suspendidos hasta completar las valoraciones válidas (vea el panel de la hoja M).")
A4: I = influencia ejercida; D = dependencia recibida. Los porcentajes son participaciones del total de cada potencia. Los rangos conservan empates.
N33: Auxiliar para los gráficos nativos de Excel (no edite). Un valor negativo (-1) significa «sin dato»: queda fuera de los ejes y Excel no dibuja ese punto.
A34: N.º | B34: Variable | C34: I directa % | D34: D directa % | E34: Rango I M1 | F34: Rango D M1 | G34: Papel en M1 | H34: I en M6 % | I34: D en M6 % | J34: Rango I M6 | K34: Rango D M6 | L34: Papel en M6 | N34: Dependencia M1 | O34: Influencia M1 | Q34: Dependencia M6 | R34: Influencia M6 | T34: Corte D · x | U34: Corte D · y | V34: Corte I · x | W34: Corte I · y | Y34: Corte D · x | Z34: Corte D · y | AA34: Corte I · x | AB34: Corte I · y
A35: 1 | B35: =IF($A35<=nVariables,M!B10,"") | C35: =IF(AND(matrizOK,$A35<=nVariables,'M1'!$C$9>0),'M1'!E10,IF(AND(matrizOK,$A35<=nVariables),"Sin recorridos","")) | D35: =IF(AND(matrizOK,$A35<=nVariables,'M1'!$C$9>0),'M1'!F10,IF(AND(matrizOK,$A35<=nVariables),"Sin recorridos","")) | E35: =IF(AND(matrizOK,$A35<=nVariables,'M1'!$C$9>0),'M1'!G10,IF(AND(matrizOK,$A35<=nVariables),"Sin recorridos","")) | F35: =IF(AND(matrizOK,$A35<=nVariables,'M1'!$C$9>0),'M1'!H10,IF(AND(matrizOK,$A35<=nVariables),"Sin recorridos","")) | G35: =IF(AND(matrizOK,$A35<=nVariables,'M1'!$C$9>0),'M1'!I10,IF(AND(matrizOK,$A35<=nVariables),"Sin recorridos","")) | H35: =IF(AND(matrizOK,$A35<=nVariables,'M6'!$C$9>0),'M6'!E10,IF(AND(matrizOK,$A35<=nVariables),"Sin recorridos","")) | I35: =IF(AND(matrizOK,$A35<=nVariables,'M6'!$C$9>0),'M6'!F10,IF(AND(matrizOK,$A35<=nVariables),"Sin recorridos","")) | J35: =IF(AND(matrizOK,$A35<=nVariables,'M6'!$C$9>0),'M6'!G10,IF(AND(matrizOK,$A35<=nVariables),"Sin recorridos","")) | K35: =IF(AND(matrizOK,$A35<=nVariables,'M6'!$C$9>0),'M6'!H10,IF(AND(matrizOK,$A35<=nVariables),"Sin recorridos","")) | L35: =IF(AND(matrizOK,$A35<=nVariables,'M6'!$C$9>0),'M6'!I10,IF(AND(matrizOK,$A35<=nVariables),"Sin recorridos","")) | N35: =IF(AND(matrizOK,$A35<=nVariables,'M1'!$C$9>0),'M1'!F10,-1) | O35: =IF(AND(matrizOK,$A35<=nVariables,'M1'!$C$9>0),'M1'!E10,-1) | Q35: =IF(AND(matrizOK,$A35<=nVariables,'M6'!$C$9>0),'M6'!F10,-1) | R35: =IF(AND(matrizOK,$A35<=nVariables,'M6'!$C$9>0),'M6'!E10,-1) | T35: =IF(AND(matrizOK,'M1'!$C$9>0,N('M1'!$C$51)>0,N('M1'!$D$51)>0),'M1'!$F$51,-1) | U35: =IF(AND(matrizOK,'M1'!$C$9>0,N('M1'!$C$51)>0,N('M1'!$D$51)>0),0,-1) | V35: =IF(AND(matrizOK,'M1'!$C$9>0,N('M1'!$C$51)>0,N('M1'!$D$51)>0),0,-1) | W35: =IF(AND(matrizOK,'M1'!$C$9>0,N('M1'!$C$51)>0,N('M1'!$D$51)>0),'M1'!$E$51,-1) | Y35: =IF(AND(matrizOK,'M6'!$C$9>0,N('M6'!$C$51)>0,N('M6'!$D$51)>0),'M6'!$F$51,-1) | Z35: =IF(AND(matrizOK,'M6'!$C$9>0,N('M6'!$C$51)>0,N('M6'!$D$51)>0),0,-1) | AA35: =IF(AND(matrizOK,'M6'!$C$9>0,N('M6'!$C$51)>0,N('M6'!$D$51)>0),0,-1) | AB35: =IF(AND(matrizOK,'M6'!$C$9>0,N('M6'!$C$51)>0,N('M6'!$D$51)>0),'M6'!$E$51,-1)
A36: 2 | B36: =IF($A36<=nVariables,M!B11,"") | C36: =IF(AND(matrizOK,$A36<=nVariables,'M1'!$C$9>0),'M1'!E11,IF(AND(matrizOK,$A36<=nVariables),"Sin recorridos","")) | D36: =IF(AND(matrizOK,$A36<=nVariables,'M1'!$C$9>0),'M1'!F11,IF(AND(matrizOK,$A36<=nVariables),"Sin recorridos","")) | E36: =IF(AND(matrizOK,$A36<=nVariables,'M1'!$C$9>0),'M1'!G11,IF(AND(matrizOK,$A36<=nVariables),"Sin recorridos","")) | F36: =IF(AND(matrizOK,$A36<=nVariables,'M1'!$C$9>0),'M1'!H11,IF(AND(matrizOK,$A36<=nVariables),"Sin recorridos","")) | G36: =IF(AND(matrizOK,$A36<=nVariables,'M1'!$C$9>0),'M1'!I11,IF(AND(matrizOK,$A36<=nVariables),"Sin recorridos","")) | H36: =IF(AND(matrizOK,$A36<=nVariables,'M6'!$C$9>0),'M6'!E11,IF(AND(matrizOK,$A36<=nVariables),"Sin recorridos","")) | I36: =IF(AND(matrizOK,$A36<=nVariables,'M6'!$C$9>0),'M6'!F11,IF(AND(matrizOK,$A36<=nVariables),"Sin recorridos","")) | J36: =IF(AND(matrizOK,$A36<=nVariables,'M6'!$C$9>0),'M6'!G11,IF(AND(matrizOK,$A36<=nVariables),"Sin recorridos","")) | K36: =IF(AND(matrizOK,$A36<=nVariables,'M6'!$C$9>0),'M6'!H11,IF(AND(matrizOK,$A36<=nVariables),"Sin recorridos","")) | L36: =IF(AND(matrizOK,$A36<=nVariables,'M6'!$C$9>0),'M6'!I11,IF(AND(matrizOK,$A36<=nVariables),"Sin recorridos","")) | N36: =IF(AND(matrizOK,$A36<=nVariables,'M1'!$C$9>0),'M1'!F11,-1) | O36: =IF(AND(matrizOK,$A36<=nVariables,'M1'!$C$9>0),'M1'!E11,-1) | Q36: =IF(AND(matrizOK,$A36<=nVariables,'M6'!$C$9>0),'M6'!F11,-1) | R36: =IF(AND(matrizOK,$A36<=nVariables,'M6'!$C$9>0),'M6'!E11,-1) | T36: =IF(AND(matrizOK,'M1'!$C$9>0,N('M1'!$C$51)>0,N('M1'!$D$51)>0),'M1'!$F$51,-1) | U36: =IF(AND(matrizOK,'M1'!$C$9>0,N('M1'!$C$51)>0,N('M1'!$D$51)>0),MAX('M1'!$E$10:$E$49)*1.1,-1) | V36: =IF(AND(matrizOK,'M1'!$C$9>0,N('M1'!$C$51)>0,N('M1'!$D$51)>0),MAX('M1'!$F$10:$F$49)*1.1,-1) | W36: =IF(AND(matrizOK,'M1'!$C$9>0,N('M1'!$C$51)>0,N('M1'!$D$51)>0),'M1'!$E$51,-1) | Y36: =IF(AND(matrizOK,'M6'!$C$9>0,N('M6'!$C$51)>0,N('M6'!$D$51)>0),'M6'!$F$51,-1) | Z36: =IF(AND(matrizOK,'M6'!$C$9>0,N('M6'!$C$51)>0,N('M6'!$D$51)>0),MAX('M6'!$E$10:$E$49)*1.1,-1) | AA36: =IF(AND(matrizOK,'M6'!$C$9>0,N('M6'!$C$51)>0,N('M6'!$D$51)>0),MAX('M6'!$F$10:$F$49)*1.1,-1) | AB36: =IF(AND(matrizOK,'M6'!$C$9>0,N('M6'!$C$51)>0,N('M6'!$D$51)>0),'M6'!$E$51,-1)
A37: 3 | B37: =IF($A37<=nVariables,M!B12,"") | C37: =IF(AND(matrizOK,$A37<=nVariables,'M1'!$C$9>0),'M1'!E12,IF(AND(matrizOK,$A37<=nVariables),"Sin recorridos","")) | D37: =IF(AND(matrizOK,$A37<=nVariables,'M1'!$C$9>0),'M1'!F12,IF(AND(matrizOK,$A37<=nVariables),"Sin recorridos","")) | E37: =IF(AND(matrizOK,$A37<=nVariables,'M1'!$C$9>0),'M1'!G12,IF(AND(matrizOK,$A37<=nVariables),"Sin recorridos","")) | F37: =IF(AND(matrizOK,$A37<=nVariables,'M1'!$C$9>0),'M1'!H12,IF(AND(matrizOK,$A37<=nVariables),"Sin recorridos","")) | G37: =IF(AND(matrizOK,$A37<=nVariables,'M1'!$C$9>0),'M1'!I12,IF(AND(matrizOK,$A37<=nVariables),"Sin recorridos","")) | H37: =IF(AND(matrizOK,$A37<=nVariables,'M6'!$C$9>0),'M6'!E12,IF(AND(matrizOK,$A37<=nVariables),"Sin recorridos","")) | I37: =IF(AND(matrizOK,$A37<=nVariables,'M6'!$C$9>0),'M6'!F12,IF(AND(matrizOK,$A37<=nVariables),"Sin recorridos","")) | J37: =IF(AND(matrizOK,$A37<=nVariables,'M6'!$C$9>0),'M6'!G12,IF(AND(matrizOK,$A37<=nVariables),"Sin recorridos","")) | K37: =IF(AND(matrizOK,$A37<=nVariables,'M6'!$C$9>0),'M6'!H12,IF(AND(matrizOK,$A37<=nVariables),"Sin recorridos","")) | L37: =IF(AND(matrizOK,$A37<=nVariables,'M6'!$C$9>0),'M6'!I12,IF(AND(matrizOK,$A37<=nVariables),"Sin recorridos","")) | N37: =IF(AND(matrizOK,$A37<=nVariables,'M1'!$C$9>0),'M1'!F12,-1) | O37: =IF(AND(matrizOK,$A37<=nVariables,'M1'!$C$9>0),'M1'!E12,-1) | Q37: =IF(AND(matrizOK,$A37<=nVariables,'M6'!$C$9>0),'M6'!F12,-1) | R37: =IF(AND(matrizOK,$A37<=nVariables,'M6'!$C$9>0),'M6'!E12,-1)
A38: 4 | B38: =IF($A38<=nVariables,M!B13,"") | C38: =IF(AND(matrizOK,$A38<=nVariables,'M1'!$C$9>0),'M1'!E13,IF(AND(matrizOK,$A38<=nVariables),"Sin recorridos","")) | D38: =IF(AND(matrizOK,$A38<=nVariables,'M1'!$C$9>0),'M1'!F13,IF(AND(matrizOK,$A38<=nVariables),"Sin recorridos","")) | E38: =IF(AND(matrizOK,$A38<=nVariables,'M1'!$C$9>0),'M1'!G13,IF(AND(matrizOK,$A38<=nVariables),"Sin recorridos","")) | F38: =IF(AND(matrizOK,$A38<=nVariables,'M1'!$C$9>0),'M1'!H13,IF(AND(matrizOK,$A38<=nVariables),"Sin recorridos","")) | G38: =IF(AND(matrizOK,$A38<=nVariables,'M1'!$C$9>0),'M1'!I13,IF(AND(matrizOK,$A38<=nVariables),"Sin recorridos","")) | H38: =IF(AND(matrizOK,$A38<=nVariables,'M6'!$C$9>0),'M6'!E13,IF(AND(matrizOK,$A38<=nVariables),"Sin recorridos","")) | I38: =IF(AND(matrizOK,$A38<=nVariables,'M6'!$C$9>0),'M6'!F13,IF(AND(matrizOK,$A38<=nVariables),"Sin recorridos","")) | J38: =IF(AND(matrizOK,$A38<=nVariables,'M6'!$C$9>0),'M6'!G13,IF(AND(matrizOK,$A38<=nVariables),"Sin recorridos","")) | K38: =IF(AND(matrizOK,$A38<=nVariables,'M6'!$C$9>0),'M6'!H13,IF(AND(matrizOK,$A38<=nVariables),"Sin recorridos","")) | L38: =IF(AND(matrizOK,$A38<=nVariables,'M6'!$C$9>0),'M6'!I13,IF(AND(matrizOK,$A38<=nVariables),"Sin recorridos","")) | N38: =IF(AND(matrizOK,$A38<=nVariables,'M1'!$C$9>0),'M1'!F13,-1) | O38: =IF(AND(matrizOK,$A38<=nVariables,'M1'!$C$9>0),'M1'!E13,-1) | Q38: =IF(AND(matrizOK,$A38<=nVariables,'M6'!$C$9>0),'M6'!F13,-1) | R38: =IF(AND(matrizOK,$A38<=nVariables,'M6'!$C$9>0),'M6'!E13,-1)
A39: 5 | B39: =IF($A39<=nVariables,M!B14,"") | C39: =IF(AND(matrizOK,$A39<=nVariables,'M1'!$C$9>0),'M1'!E14,IF(AND(matrizOK,$A39<=nVariables),"Sin recorridos","")) | D39: =IF(AND(matrizOK,$A39<=nVariables,'M1'!$C$9>0),'M1'!F14,IF(AND(matrizOK,$A39<=nVariables),"Sin recorridos","")) | E39: =IF(AND(matrizOK,$A39<=nVariables,'M1'!$C$9>0),'M1'!G14,IF(AND(matrizOK,$A39<=nVariables),"Sin recorridos","")) | F39: =IF(AND(matrizOK,$A39<=nVariables,'M1'!$C$9>0),'M1'!H14,IF(AND(matrizOK,$A39<=nVariables),"Sin recorridos","")) | G39: =IF(AND(matrizOK,$A39<=nVariables,'M1'!$C$9>0),'M1'!I14,IF(AND(matrizOK,$A39<=nVariables),"Sin recorridos","")) | H39: =IF(AND(matrizOK,$A39<=nVariables,'M6'!$C$9>0),'M6'!E14,IF(AND(matrizOK,$A39<=nVariables),"Sin recorridos","")) | I39: =IF(AND(matrizOK,$A39<=nVariables,'M6'!$C$9>0),'M6'!F14,IF(AND(matrizOK,$A39<=nVariables),"Sin recorridos","")) | J39: =IF(AND(matrizOK,$A39<=nVariables,'M6'!$C$9>0),'M6'!G14,IF(AND(matrizOK,$A39<=nVariables),"Sin recorridos","")) | K39: =IF(AND(matrizOK,$A39<=nVariables,'M6'!$C$9>0),'M6'!H14,IF(AND(matrizOK,$A39<=nVariables),"Sin recorridos","")) | L39: =IF(AND(matrizOK,$A39<=nVariables,'M6'!$C$9>0),'M6'!I14,IF(AND(matrizOK,$A39<=nVariables),"Sin recorridos","")) | N39: =IF(AND(matrizOK,$A39<=nVariables,'M1'!$C$9>0),'M1'!F14,-1) | O39: =IF(AND(matrizOK,$A39<=nVariables,'M1'!$C$9>0),'M1'!E14,-1) | Q39: =IF(AND(matrizOK,$A39<=nVariables,'M6'!$C$9>0),'M6'!F14,-1) | R39: =IF(AND(matrizOK,$A39<=nVariables,'M6'!$C$9>0),'M6'!E14,-1)
A40: 6 | B40: =IF($A40<=nVariables,M!B15,"") | C40: =IF(AND(matrizOK,$A40<=nVariables,'M1'!$C$9>0),'M1'!E15,IF(AND(matrizOK,$A40<=nVariables),"Sin recorridos","")) | D40: =IF(AND(matrizOK,$A40<=nVariables,'M1'!$C$9>0),'M1'!F15,IF(AND(matrizOK,$A40<=nVariables),"Sin recorridos","")) | E40: =IF(AND(matrizOK,$A40<=nVariables,'M1'!$C$9>0),'M1'!G15,IF(AND(matrizOK,$A40<=nVariables),"Sin recorridos","")) | F40: =IF(AND(matrizOK,$A40<=nVariables,'M1'!$C$9>0),'M1'!H15,IF(AND(matrizOK,$A40<=nVariables),"Sin recorridos","")) | G40: =IF(AND(matrizOK,$A40<=nVariables,'M1'!$C$9>0),'M1'!I15,IF(AND(matrizOK,$A40<=nVariables),"Sin recorridos","")) | H40: =IF(AND(matrizOK,$A40<=nVariables,'M6'!$C$9>0),'M6'!E15,IF(AND(matrizOK,$A40<=nVariables),"Sin recorridos","")) | I40: =IF(AND(matrizOK,$A40<=nVariables,'M6'!$C$9>0),'M6'!F15,IF(AND(matrizOK,$A40<=nVariables),"Sin recorridos","")) | J40: =IF(AND(matrizOK,$A40<=nVariables,'M6'!$C$9>0),'M6'!G15,IF(AND(matrizOK,$A40<=nVariables),"Sin recorridos","")) | K40: =IF(AND(matrizOK,$A40<=nVariables,'M6'!$C$9>0),'M6'!H15,IF(AND(matrizOK,$A40<=nVariables),"Sin recorridos","")) | L40: =IF(AND(matrizOK,$A40<=nVariables,'M6'!$C$9>0),'M6'!I15,IF(AND(matrizOK,$A40<=nVariables),"Sin recorridos","")) | N40: =IF(AND(matrizOK,$A40<=nVariables,'M1'!$C$9>0),'M1'!F15,-1) | O40: =IF(AND(matrizOK,$A40<=nVariables,'M1'!$C$9>0),'M1'!E15,-1) | Q40: =IF(AND(matrizOK,$A40<=nVariables,'M6'!$C$9>0),'M6'!F15,-1) | R40: =IF(AND(matrizOK,$A40<=nVariables,'M6'!$C$9>0),'M6'!E15,-1)
A41: 7 | B41: =IF($A41<=nVariables,M!B16,"") | C41: =IF(AND(matrizOK,$A41<=nVariables,'M1'!$C$9>0),'M1'!E16,IF(AND(matrizOK,$A41<=nVariables),"Sin recorridos","")) | D41: =IF(AND(matrizOK,$A41<=nVariables,'M1'!$C$9>0),'M1'!F16,IF(AND(matrizOK,$A41<=nVariables),"Sin recorridos","")) | E41: =IF(AND(matrizOK,$A41<=nVariables,'M1'!$C$9>0),'M1'!G16,IF(AND(matrizOK,$A41<=nVariables),"Sin recorridos","")) | F41: =IF(AND(matrizOK,$A41<=nVariables,'M1'!$C$9>0),'M1'!H16,IF(AND(matrizOK,$A41<=nVariables),"Sin recorridos","")) | G41: =IF(AND(matrizOK,$A41<=nVariables,'M1'!$C$9>0),'M1'!I16,IF(AND(matrizOK,$A41<=nVariables),"Sin recorridos","")) | H41: =IF(AND(matrizOK,$A41<=nVariables,'M6'!$C$9>0),'M6'!E16,IF(AND(matrizOK,$A41<=nVariables),"Sin recorridos","")) | I41: =IF(AND(matrizOK,$A41<=nVariables,'M6'!$C$9>0),'M6'!F16,IF(AND(matrizOK,$A41<=nVariables),"Sin recorridos","")) | J41: =IF(AND(matrizOK,$A41<=nVariables,'M6'!$C$9>0),'M6'!G16,IF(AND(matrizOK,$A41<=nVariables),"Sin recorridos","")) | K41: =IF(AND(matrizOK,$A41<=nVariables,'M6'!$C$9>0),'M6'!H16,IF(AND(matrizOK,$A41<=nVariables),"Sin recorridos","")) | L41: =IF(AND(matrizOK,$A41<=nVariables,'M6'!$C$9>0),'M6'!I16,IF(AND(matrizOK,$A41<=nVariables),"Sin recorridos","")) | N41: =IF(AND(matrizOK,$A41<=nVariables,'M1'!$C$9>0),'M1'!F16,-1) | O41: =IF(AND(matrizOK,$A41<=nVariables,'M1'!$C$9>0),'M1'!E16,-1) | Q41: =IF(AND(matrizOK,$A41<=nVariables,'M6'!$C$9>0),'M6'!F16,-1) | R41: =IF(AND(matrizOK,$A41<=nVariables,'M6'!$C$9>0),'M6'!E16,-1)
A42: 8 | B42: =IF($A42<=nVariables,M!B17,"") | C42: =IF(AND(matrizOK,$A42<=nVariables,'M1'!$C$9>0),'M1'!E17,IF(AND(matrizOK,$A42<=nVariables),"Sin recorridos","")) | D42: =IF(AND(matrizOK,$A42<=nVariables,'M1'!$C$9>0),'M1'!F17,IF(AND(matrizOK,$A42<=nVariables),"Sin recorridos","")) | E42: =IF(AND(matrizOK,$A42<=nVariables,'M1'!$C$9>0),'M1'!G17,IF(AND(matrizOK,$A42<=nVariables),"Sin recorridos","")) | F42: =IF(AND(matrizOK,$A42<=nVariables,'M1'!$C$9>0),'M1'!H17,IF(AND(matrizOK,$A42<=nVariables),"Sin recorridos","")) | G42: =IF(AND(matrizOK,$A42<=nVariables,'M1'!$C$9>0),'M1'!I17,IF(AND(matrizOK,$A42<=nVariables),"Sin recorridos","")) | H42: =IF(AND(matrizOK,$A42<=nVariables,'M6'!$C$9>0),'M6'!E17,IF(AND(matrizOK,$A42<=nVariables),"Sin recorridos","")) | I42: =IF(AND(matrizOK,$A42<=nVariables,'M6'!$C$9>0),'M6'!F17,IF(AND(matrizOK,$A42<=nVariables),"Sin recorridos","")) | J42: =IF(AND(matrizOK,$A42<=nVariables,'M6'!$C$9>0),'M6'!G17,IF(AND(matrizOK,$A42<=nVariables),"Sin recorridos","")) | K42: =IF(AND(matrizOK,$A42<=nVariables,'M6'!$C$9>0),'M6'!H17,IF(AND(matrizOK,$A42<=nVariables),"Sin recorridos","")) | L42: =IF(AND(matrizOK,$A42<=nVariables,'M6'!$C$9>0),'M6'!I17,IF(AND(matrizOK,$A42<=nVariables),"Sin recorridos","")) | N42: =IF(AND(matrizOK,$A42<=nVariables,'M1'!$C$9>0),'M1'!F17,-1) | O42: =IF(AND(matrizOK,$A42<=nVariables,'M1'!$C$9>0),'M1'!E17,-1) | Q42: =IF(AND(matrizOK,$A42<=nVariables,'M6'!$C$9>0),'M6'!F17,-1) | R42: =IF(AND(matrizOK,$A42<=nVariables,'M6'!$C$9>0),'M6'!E17,-1)
A43: 9 | B43: =IF($A43<=nVariables,M!B18,"") | C43: =IF(AND(matrizOK,$A43<=nVariables,'M1'!$C$9>0),'M1'!E18,IF(AND(matrizOK,$A43<=nVariables),"Sin recorridos","")) | D43: =IF(AND(matrizOK,$A43<=nVariables,'M1'!$C$9>0),'M1'!F18,IF(AND(matrizOK,$A43<=nVariables),"Sin recorridos","")) | E43: =IF(AND(matrizOK,$A43<=nVariables,'M1'!$C$9>0),'M1'!G18,IF(AND(matrizOK,$A43<=nVariables),"Sin recorridos","")) | F43: =IF(AND(matrizOK,$A43<=nVariables,'M1'!$C$9>0),'M1'!H18,IF(AND(matrizOK,$A43<=nVariables),"Sin recorridos","")) | G43: =IF(AND(matrizOK,$A43<=nVariables,'M1'!$C$9>0),'M1'!I18,IF(AND(matrizOK,$A43<=nVariables),"Sin recorridos","")) | H43: =IF(AND(matrizOK,$A43<=nVariables,'M6'!$C$9>0),'M6'!E18,IF(AND(matrizOK,$A43<=nVariables),"Sin recorridos","")) | I43: =IF(AND(matrizOK,$A43<=nVariables,'M6'!$C$9>0),'M6'!F18,IF(AND(matrizOK,$A43<=nVariables),"Sin recorridos","")) | J43: =IF(AND(matrizOK,$A43<=nVariables,'M6'!$C$9>0),'M6'!G18,IF(AND(matrizOK,$A43<=nVariables),"Sin recorridos","")) | K43: =IF(AND(matrizOK,$A43<=nVariables,'M6'!$C$9>0),'M6'!H18,IF(AND(matrizOK,$A43<=nVariables),"Sin recorridos","")) | L43: =IF(AND(matrizOK,$A43<=nVariables,'M6'!$C$9>0),'M6'!I18,IF(AND(matrizOK,$A43<=nVariables),"Sin recorridos","")) | N43: =IF(AND(matrizOK,$A43<=nVariables,'M1'!$C$9>0),'M1'!F18,-1) | O43: =IF(AND(matrizOK,$A43<=nVariables,'M1'!$C$9>0),'M1'!E18,-1) | Q43: =IF(AND(matrizOK,$A43<=nVariables,'M6'!$C$9>0),'M6'!F18,-1) | R43: =IF(AND(matrizOK,$A43<=nVariables,'M6'!$C$9>0),'M6'!E18,-1)
A44: 10 | B44: =IF($A44<=nVariables,M!B19,"") | C44: =IF(AND(matrizOK,$A44<=nVariables,'M1'!$C$9>0),'M1'!E19,IF(AND(matrizOK,$A44<=nVariables),"Sin recorridos","")) | D44: =IF(AND(matrizOK,$A44<=nVariables,'M1'!$C$9>0),'M1'!F19,IF(AND(matrizOK,$A44<=nVariables),"Sin recorridos","")) | E44: =IF(AND(matrizOK,$A44<=nVariables,'M1'!$C$9>0),'M1'!G19,IF(AND(matrizOK,$A44<=nVariables),"Sin recorridos","")) | F44: =IF(AND(matrizOK,$A44<=nVariables,'M1'!$C$9>0),'M1'!H19,IF(AND(matrizOK,$A44<=nVariables),"Sin recorridos","")) | G44: =IF(AND(matrizOK,$A44<=nVariables,'M1'!$C$9>0),'M1'!I19,IF(AND(matrizOK,$A44<=nVariables),"Sin recorridos","")) | H44: =IF(AND(matrizOK,$A44<=nVariables,'M6'!$C$9>0),'M6'!E19,IF(AND(matrizOK,$A44<=nVariables),"Sin recorridos","")) | I44: =IF(AND(matrizOK,$A44<=nVariables,'M6'!$C$9>0),'M6'!F19,IF(AND(matrizOK,$A44<=nVariables),"Sin recorridos","")) | J44: =IF(AND(matrizOK,$A44<=nVariables,'M6'!$C$9>0),'M6'!G19,IF(AND(matrizOK,$A44<=nVariables),"Sin recorridos","")) | K44: =IF(AND(matrizOK,$A44<=nVariables,'M6'!$C$9>0),'M6'!H19,IF(AND(matrizOK,$A44<=nVariables),"Sin recorridos","")) | L44: =IF(AND(matrizOK,$A44<=nVariables,'M6'!$C$9>0),'M6'!I19,IF(AND(matrizOK,$A44<=nVariables),"Sin recorridos","")) | N44: =IF(AND(matrizOK,$A44<=nVariables,'M1'!$C$9>0),'M1'!F19,-1) | O44: =IF(AND(matrizOK,$A44<=nVariables,'M1'!$C$9>0),'M1'!E19,-1) | Q44: =IF(AND(matrizOK,$A44<=nVariables,'M6'!$C$9>0),'M6'!F19,-1) | R44: =IF(AND(matrizOK,$A44<=nVariables,'M6'!$C$9>0),'M6'!E19,-1)
A45: 11 | B45: =IF($A45<=nVariables,M!B20,"") | C45: =IF(AND(matrizOK,$A45<=nVariables,'M1'!$C$9>0),'M1'!E20,IF(AND(matrizOK,$A45<=nVariables),"Sin recorridos","")) | D45: =IF(AND(matrizOK,$A45<=nVariables,'M1'!$C$9>0),'M1'!F20,IF(AND(matrizOK,$A45<=nVariables),"Sin recorridos","")) | E45: =IF(AND(matrizOK,$A45<=nVariables,'M1'!$C$9>0),'M1'!G20,IF(AND(matrizOK,$A45<=nVariables),"Sin recorridos","")) | F45: =IF(AND(matrizOK,$A45<=nVariables,'M1'!$C$9>0),'M1'!H20,IF(AND(matrizOK,$A45<=nVariables),"Sin recorridos","")) | G45: =IF(AND(matrizOK,$A45<=nVariables,'M1'!$C$9>0),'M1'!I20,IF(AND(matrizOK,$A45<=nVariables),"Sin recorridos","")) | H45: =IF(AND(matrizOK,$A45<=nVariables,'M6'!$C$9>0),'M6'!E20,IF(AND(matrizOK,$A45<=nVariables),"Sin recorridos","")) | I45: =IF(AND(matrizOK,$A45<=nVariables,'M6'!$C$9>0),'M6'!F20,IF(AND(matrizOK,$A45<=nVariables),"Sin recorridos","")) | J45: =IF(AND(matrizOK,$A45<=nVariables,'M6'!$C$9>0),'M6'!G20,IF(AND(matrizOK,$A45<=nVariables),"Sin recorridos","")) | K45: =IF(AND(matrizOK,$A45<=nVariables,'M6'!$C$9>0),'M6'!H20,IF(AND(matrizOK,$A45<=nVariables),"Sin recorridos","")) | L45: =IF(AND(matrizOK,$A45<=nVariables,'M6'!$C$9>0),'M6'!I20,IF(AND(matrizOK,$A45<=nVariables),"Sin recorridos","")) | N45: =IF(AND(matrizOK,$A45<=nVariables,'M1'!$C$9>0),'M1'!F20,-1) | O45: =IF(AND(matrizOK,$A45<=nVariables,'M1'!$C$9>0),'M1'!E20,-1) | Q45: =IF(AND(matrizOK,$A45<=nVariables,'M6'!$C$9>0),'M6'!F20,-1) | R45: =IF(AND(matrizOK,$A45<=nVariables,'M6'!$C$9>0),'M6'!E20,-1)
A46: 12 | B46: =IF($A46<=nVariables,M!B21,"") | C46: =IF(AND(matrizOK,$A46<=nVariables,'M1'!$C$9>0),'M1'!E21,IF(AND(matrizOK,$A46<=nVariables),"Sin recorridos","")) | D46: =IF(AND(matrizOK,$A46<=nVariables,'M1'!$C$9>0),'M1'!F21,IF(AND(matrizOK,$A46<=nVariables),"Sin recorridos","")) | E46: =IF(AND(matrizOK,$A46<=nVariables,'M1'!$C$9>0),'M1'!G21,IF(AND(matrizOK,$A46<=nVariables),"Sin recorridos","")) | F46: =IF(AND(matrizOK,$A46<=nVariables,'M1'!$C$9>0),'M1'!H21,IF(AND(matrizOK,$A46<=nVariables),"Sin recorridos","")) | G46: =IF(AND(matrizOK,$A46<=nVariables,'M1'!$C$9>0),'M1'!I21,IF(AND(matrizOK,$A46<=nVariables),"Sin recorridos","")) | H46: =IF(AND(matrizOK,$A46<=nVariables,'M6'!$C$9>0),'M6'!E21,IF(AND(matrizOK,$A46<=nVariables),"Sin recorridos","")) | I46: =IF(AND(matrizOK,$A46<=nVariables,'M6'!$C$9>0),'M6'!F21,IF(AND(matrizOK,$A46<=nVariables),"Sin recorridos","")) | J46: =IF(AND(matrizOK,$A46<=nVariables,'M6'!$C$9>0),'M6'!G21,IF(AND(matrizOK,$A46<=nVariables),"Sin recorridos","")) | K46: =IF(AND(matrizOK,$A46<=nVariables,'M6'!$C$9>0),'M6'!H21,IF(AND(matrizOK,$A46<=nVariables),"Sin recorridos","")) | L46: =IF(AND(matrizOK,$A46<=nVariables,'M6'!$C$9>0),'M6'!I21,IF(AND(matrizOK,$A46<=nVariables),"Sin recorridos","")) | N46: =IF(AND(matrizOK,$A46<=nVariables,'M1'!$C$9>0),'M1'!F21,-1) | O46: =IF(AND(matrizOK,$A46<=nVariables,'M1'!$C$9>0),'M1'!E21,-1) | Q46: =IF(AND(matrizOK,$A46<=nVariables,'M6'!$C$9>0),'M6'!F21,-1) | R46: =IF(AND(matrizOK,$A46<=nVariables,'M6'!$C$9>0),'M6'!E21,-1)
A47: 13 | B47: =IF($A47<=nVariables,M!B22,"") | C47: =IF(AND(matrizOK,$A47<=nVariables,'M1'!$C$9>0),'M1'!E22,IF(AND(matrizOK,$A47<=nVariables),"Sin recorridos","")) | D47: =IF(AND(matrizOK,$A47<=nVariables,'M1'!$C$9>0),'M1'!F22,IF(AND(matrizOK,$A47<=nVariables),"Sin recorridos","")) | E47: =IF(AND(matrizOK,$A47<=nVariables,'M1'!$C$9>0),'M1'!G22,IF(AND(matrizOK,$A47<=nVariables),"Sin recorridos","")) | F47: =IF(AND(matrizOK,$A47<=nVariables,'M1'!$C$9>0),'M1'!H22,IF(AND(matrizOK,$A47<=nVariables),"Sin recorridos","")) | G47: =IF(AND(matrizOK,$A47<=nVariables,'M1'!$C$9>0),'M1'!I22,IF(AND(matrizOK,$A47<=nVariables),"Sin recorridos","")) | H47: =IF(AND(matrizOK,$A47<=nVariables,'M6'!$C$9>0),'M6'!E22,IF(AND(matrizOK,$A47<=nVariables),"Sin recorridos","")) | I47: =IF(AND(matrizOK,$A47<=nVariables,'M6'!$C$9>0),'M6'!F22,IF(AND(matrizOK,$A47<=nVariables),"Sin recorridos","")) | J47: =IF(AND(matrizOK,$A47<=nVariables,'M6'!$C$9>0),'M6'!G22,IF(AND(matrizOK,$A47<=nVariables),"Sin recorridos","")) | K47: =IF(AND(matrizOK,$A47<=nVariables,'M6'!$C$9>0),'M6'!H22,IF(AND(matrizOK,$A47<=nVariables),"Sin recorridos","")) | L47: =IF(AND(matrizOK,$A47<=nVariables,'M6'!$C$9>0),'M6'!I22,IF(AND(matrizOK,$A47<=nVariables),"Sin recorridos","")) | N47: =IF(AND(matrizOK,$A47<=nVariables,'M1'!$C$9>0),'M1'!F22,-1) | O47: =IF(AND(matrizOK,$A47<=nVariables,'M1'!$C$9>0),'M1'!E22,-1) | Q47: =IF(AND(matrizOK,$A47<=nVariables,'M6'!$C$9>0),'M6'!F22,-1) | R47: =IF(AND(matrizOK,$A47<=nVariables,'M6'!$C$9>0),'M6'!E22,-1)
A48: 14 | B48: =IF($A48<=nVariables,M!B23,"") | C48: =IF(AND(matrizOK,$A48<=nVariables,'M1'!$C$9>0),'M1'!E23,IF(AND(matrizOK,$A48<=nVariables),"Sin recorridos","")) | D48: =IF(AND(matrizOK,$A48<=nVariables,'M1'!$C$9>0),'M1'!F23,IF(AND(matrizOK,$A48<=nVariables),"Sin recorridos","")) | E48: =IF(AND(matrizOK,$A48<=nVariables,'M1'!$C$9>0),'M1'!G23,IF(AND(matrizOK,$A48<=nVariables),"Sin recorridos","")) | F48: =IF(AND(matrizOK,$A48<=nVariables,'M1'!$C$9>0),'M1'!H23,IF(AND(matrizOK,$A48<=nVariables),"Sin recorridos","")) | G48: =IF(AND(matrizOK,$A48<=nVariables,'M1'!$C$9>0),'M1'!I23,IF(AND(matrizOK,$A48<=nVariables),"Sin recorridos","")) | H48: =IF(AND(matrizOK,$A48<=nVariables,'M6'!$C$9>0),'M6'!E23,IF(AND(matrizOK,$A48<=nVariables),"Sin recorridos","")) | I48: =IF(AND(matrizOK,$A48<=nVariables,'M6'!$C$9>0),'M6'!F23,IF(AND(matrizOK,$A48<=nVariables),"Sin recorridos","")) | J48: =IF(AND(matrizOK,$A48<=nVariables,'M6'!$C$9>0),'M6'!G23,IF(AND(matrizOK,$A48<=nVariables),"Sin recorridos","")) | K48: =IF(AND(matrizOK,$A48<=nVariables,'M6'!$C$9>0),'M6'!H23,IF(AND(matrizOK,$A48<=nVariables),"Sin recorridos","")) | L48: =IF(AND(matrizOK,$A48<=nVariables,'M6'!$C$9>0),'M6'!I23,IF(AND(matrizOK,$A48<=nVariables),"Sin recorridos","")) | N48: =IF(AND(matrizOK,$A48<=nVariables,'M1'!$C$9>0),'M1'!F23,-1) | O48: =IF(AND(matrizOK,$A48<=nVariables,'M1'!$C$9>0),'M1'!E23,-1) | Q48: =IF(AND(matrizOK,$A48<=nVariables,'M6'!$C$9>0),'M6'!F23,-1) | R48: =IF(AND(matrizOK,$A48<=nVariables,'M6'!$C$9>0),'M6'!E23,-1)
... A74: 40 | B74: =IF($A74<=nVariables,M!B49,"") | C74: =IF(AND(matrizOK,$A74<=nVariables,'M1'!$C$9>0),'M1'!E49,IF(AND(matrizOK,$A74<=nVariables),"Sin recorridos","")) | D74: =IF(AND(matrizOK,$A74<=nVariables,'M1'!$C$9>0),'M1'!F49,IF(AND(matrizOK,$A74<=nVariables),"Sin recorridos","")) | E74: =IF(AND(matrizOK,$A74<=nVariables,'M1'!$C$9>0),'M1'!G49,IF(AND(matrizOK,$A74<=nVariables),"Sin recorridos","")) | F74: =IF(AND(matrizOK,$A74<=nVariables,'M1'!$C$9>0),'M1'!H49,IF(AND(matrizOK,$A74<=nVariables),"Sin recorridos","")) | G74: =IF(AND(matrizOK,$A74<=nVariables,'M1'!$C$9>0),'M1'!I49,IF(AND(matrizOK,$A74<=nVariables),"Sin recorridos","")) | H74: =IF(AND(matrizOK,$A74<=nVariables,'M6'!$C$9>0),'M6'!E49,IF(AND(matrizOK,$A74<=nVariables),"Sin recorridos","")) | I74: =IF(AND(matrizOK,$A74<=nVariables,'M6'!$C$9>0),'M6'!F49,IF(AND(matrizOK,$A74<=nVariables),"Sin recorridos","")) | J74: =IF(AND(matrizOK,$A74<=nVariables,'M6'!$C$9>0),'M6'!G49,IF(AND(matrizOK,$A74<=nVariables),"Sin recorridos","")) | K74: =IF(AND(matrizOK,$A74<=nVariables,'M6'!$C$9>0),'M6'!H49,IF(AND(matrizOK,$A74<=nVariables),"Sin recorridos","")) | L74: =IF(AND(matrizOK,$A74<=nVariables,'M6'!$C$9>0),'M6'!I49,IF(AND(matrizOK,$A74<=nVariables),"Sin recorridos","")) | N74: =IF(AND(matrizOK,$A74<=nVariables,'M1'!$C$9>0),'M1'!F49,-1) | O74: =IF(AND(matrizOK,$A74<=nVariables,'M1'!$C$9>0),'M1'!E49,-1) | Q74: =IF(AND(matrizOK,$A74<=nVariables,'M6'!$C$9>0),'M6'!F49,-1) | R74: =IF(AND(matrizOK,$A74<=nVariables,'M6'!$C$9>0),'M6'!E49,-1)
A78: Puesto | B78: Orden de influencia en M6 | C78: Rango real | D78: Valor %
A79: 1 | B79: =IF(AND(matrizOK,$A79<=nVariables,'M6'!$C$9>0),INDEX('M6'!$B$10:$B$49,MATCH($A79,'M6'!$J$10:$J$49,0)),"") | C79: =IF(AND(matrizOK,$A79<=nVariables,'M6'!$C$9>0),INDEX('M6'!$G$10:$G$49,MATCH($A79,'M6'!$J$10:$J$49,0)),"") | D79: =IF(AND(matrizOK,$A79<=nVariables,'M6'!$C$9>0),INDEX('M6'!$E$10:$E$49,MATCH($A79,'M6'!$J$10:$J$49,0)),"")
A80: 2 | B80: =IF(AND(matrizOK,$A80<=nVariables,'M6'!$C$9>0),INDEX('M6'!$B$10:$B$49,MATCH($A80,'M6'!$J$10:$J$49,0)),"") | C80: =IF(AND(matrizOK,$A80<=nVariables,'M6'!$C$9>0),INDEX('M6'!$G$10:$G$49,MATCH($A80,'M6'!$J$10:$J$49,0)),"") | D80: =IF(AND(matrizOK,$A80<=nVariables,'M6'!$C$9>0),INDEX('M6'!$E$10:$E$49,MATCH($A80,'M6'!$J$10:$J$49,0)),"")
A81: 3 | B81: =IF(AND(matrizOK,$A81<=nVariables,'M6'!$C$9>0),INDEX('M6'!$B$10:$B$49,MATCH($A81,'M6'!$J$10:$J$49,0)),"") | C81: =IF(AND(matrizOK,$A81<=nVariables,'M6'!$C$9>0),INDEX('M6'!$G$10:$G$49,MATCH($A81,'M6'!$J$10:$J$49,0)),"") | D81: =IF(AND(matrizOK,$A81<=nVariables,'M6'!$C$9>0),INDEX('M6'!$E$10:$E$49,MATCH($A81,'M6'!$J$10:$J$49,0)),"")
A82: 4 | B82: =IF(AND(matrizOK,$A82<=nVariables,'M6'!$C$9>0),INDEX('M6'!$B$10:$B$49,MATCH($A82,'M6'!$J$10:$J$49,0)),"") | C82: =IF(AND(matrizOK,$A82<=nVariables,'M6'!$C$9>0),INDEX('M6'!$G$10:$G$49,MATCH($A82,'M6'!$J$10:$J$49,0)),"") | D82: =IF(AND(matrizOK,$A82<=nVariables,'M6'!$C$9>0),INDEX('M6'!$E$10:$E$49,MATCH($A82,'M6'!$J$10:$J$49,0)),"")
A83: 5 | B83: =IF(AND(matrizOK,$A83<=nVariables,'M6'!$C$9>0),INDEX('M6'!$B$10:$B$49,MATCH($A83,'M6'!$J$10:$J$49,0)),"") | C83: =IF(AND(matrizOK,$A83<=nVariables,'M6'!$C$9>0),INDEX('M6'!$G$10:$G$49,MATCH($A83,'M6'!$J$10:$J$49,0)),"") | D83: =IF(AND(matrizOK,$A83<=nVariables,'M6'!$C$9>0),INDEX('M6'!$E$10:$E$49,MATCH($A83,'M6'!$J$10:$J$49,0)),"")
A84: 6 | B84: =IF(AND(matrizOK,$A84<=nVariables,'M6'!$C$9>0),INDEX('M6'!$B$10:$B$49,MATCH($A84,'M6'!$J$10:$J$49,0)),"") | C84: =IF(AND(matrizOK,$A84<=nVariables,'M6'!$C$9>0),INDEX('M6'!$G$10:$G$49,MATCH($A84,'M6'!$J$10:$J$49,0)),"") | D84: =IF(AND(matrizOK,$A84<=nVariables,'M6'!$C$9>0),INDEX('M6'!$E$10:$E$49,MATCH($A84,'M6'!$J$10:$J$49,0)),"")
A85: 7 | B85: =IF(AND(matrizOK,$A85<=nVariables,'M6'!$C$9>0),INDEX('M6'!$B$10:$B$49,MATCH($A85,'M6'!$J$10:$J$49,0)),"") | C85: =IF(AND(matrizOK,$A85<=nVariables,'M6'!$C$9>0),INDEX('M6'!$G$10:$G$49,MATCH($A85,'M6'!$J$10:$J$49,0)),"") | D85: =IF(AND(matrizOK,$A85<=nVariables,'M6'!$C$9>0),INDEX('M6'!$E$10:$E$49,MATCH($A85,'M6'!$J$10:$J$49,0)),"")
A86: 8 | B86: =IF(AND(matrizOK,$A86<=nVariables,'M6'!$C$9>0),INDEX('M6'!$B$10:$B$49,MATCH($A86,'M6'!$J$10:$J$49,0)),"") | C86: =IF(AND(matrizOK,$A86<=nVariables,'M6'!$C$9>0),INDEX('M6'!$G$10:$G$49,MATCH($A86,'M6'!$J$10:$J$49,0)),"") | D86: =IF(AND(matrizOK,$A86<=nVariables,'M6'!$C$9>0),INDEX('M6'!$E$10:$E$49,MATCH($A86,'M6'!$J$10:$J$49,0)),"")
A87: 9 | B87: =IF(AND(matrizOK,$A87<=nVariables,'M6'!$C$9>0),INDEX('M6'!$B$10:$B$49,MATCH($A87,'M6'!$J$10:$J$49,0)),"") | C87: =IF(AND(matrizOK,$A87<=nVariables,'M6'!$C$9>0),INDEX('M6'!$G$10:$G$49,MATCH($A87,'M6'!$J$10:$J$49,0)),"") | D87: =IF(AND(matrizOK,$A87<=nVariables,'M6'!$C$9>0),INDEX('M6'!$E$10:$E$49,MATCH($A87,'M6'!$J$10:$J$49,0)),"")
A88: 10 | B88: =IF(AND(matrizOK,$A88<=nVariables,'M6'!$C$9>0),INDEX('M6'!$B$10:$B$49,MATCH($A88,'M6'!$J$10:$J$49,0)),"") | C88: =IF(AND(matrizOK,$A88<=nVariables,'M6'!$C$9>0),INDEX('M6'!$G$10:$G$49,MATCH($A88,'M6'!$J$10:$J$49,0)),"") | D88: =IF(AND(matrizOK,$A88<=nVariables,'M6'!$C$9>0),INDEX('M6'!$E$10:$E$49,MATCH($A88,'M6'!$J$10:$J$49,0)),"")
A89: 11 | B89: =IF(AND(matrizOK,$A89<=nVariables,'M6'!$C$9>0),INDEX('M6'!$B$10:$B$49,MATCH($A89,'M6'!$J$10:$J$49,0)),"") | C89: =IF(AND(matrizOK,$A89<=nVariables,'M6'!$C$9>0),INDEX('M6'!$G$10:$G$49,MATCH($A89,'M6'!$J$10:$J$49,0)),"") | D89: =IF(AND(matrizOK,$A89<=nVariables,'M6'!$C$9>0),INDEX('M6'!$E$10:$E$49,MATCH($A89,'M6'!$J$10:$J$49,0)),"")
A90: 12 | B90: =IF(AND(matrizOK,$A90<=nVariables,'M6'!$C$9>0),INDEX('M6'!$B$10:$B$49,MATCH($A90,'M6'!$J$10:$J$49,0)),"") | C90: =IF(AND(matrizOK,$A90<=nVariables,'M6'!$C$9>0),INDEX('M6'!$G$10:$G$49,MATCH($A90,'M6'!$J$10:$J$49,0)),"") | D90: =IF(AND(matrizOK,$A90<=nVariables,'M6'!$C$9>0),INDEX('M6'!$E$10:$E$49,MATCH($A90,'M6'!$J$10:$J$49,0)),"")
... A118: 40 | B118: =IF(AND(matrizOK,$A118<=nVariables,'M6'!$C$9>0),INDEX('M6'!$B$10:$B$49,MATCH($A118,'M6'!$J$10:$J$49,0)),"") | C118: =IF(AND(matrizOK,$A118<=nVariables,'M6'!$C$9>0),INDEX('M6'!$G$10:$G$49,MATCH($A118,'M6'!$J$10:$J$49,0)),"") | D118: =IF(AND(matrizOK,$A118<=nVariables,'M6'!$C$9>0),INDEX('M6'!$E$10:$E$49,MATCH($A118,'M6'!$J$10:$J$49,0)),"")
A121: Puesto | B121: Orden de dependencia en M6 | C121: Rango real | D121: Valor %
A122: 1 | B122: =IF(AND(matrizOK,$A122<=nVariables,'M6'!$C$9>0),INDEX('M6'!$B$10:$B$49,MATCH($A122,'M6'!$K$10:$K$49,0)),"") | C122: =IF(AND(matrizOK,$A122<=nVariables,'M6'!$C$9>0),INDEX('M6'!$H$10:$H$49,MATCH($A122,'M6'!$K$10:$K$49,0)),"") | D122: =IF(AND(matrizOK,$A122<=nVariables,'M6'!$C$9>0),INDEX('M6'!$F$10:$F$49,MATCH($A122,'M6'!$K$10:$K$49,0)),"")
A123: 2 | B123: =IF(AND(matrizOK,$A123<=nVariables,'M6'!$C$9>0),INDEX('M6'!$B$10:$B$49,MATCH($A123,'M6'!$K$10:$K$49,0)),"") | C123: =IF(AND(matrizOK,$A123<=nVariables,'M6'!$C$9>0),INDEX('M6'!$H$10:$H$49,MATCH($A123,'M6'!$K$10:$K$49,0)),"") | D123: =IF(AND(matrizOK,$A123<=nVariables,'M6'!$C$9>0),INDEX('M6'!$F$10:$F$49,MATCH($A123,'M6'!$K$10:$K$49,0)),"")
A124: 3 | B124: =IF(AND(matrizOK,$A124<=nVariables,'M6'!$C$9>0),INDEX('M6'!$B$10:$B$49,MATCH($A124,'M6'!$K$10:$K$49,0)),"") | C124: =IF(AND(matrizOK,$A124<=nVariables,'M6'!$C$9>0),INDEX('M6'!$H$10:$H$49,MATCH($A124,'M6'!$K$10:$K$49,0)),"") | D124: =IF(AND(matrizOK,$A124<=nVariables,'M6'!$C$9>0),INDEX('M6'!$F$10:$F$49,MATCH($A124,'M6'!$K$10:$K$49,0)),"")
A125: 4 | B125: =IF(AND(matrizOK,$A125<=nVariables,'M6'!$C$9>0),INDEX('M6'!$B$10:$B$49,MATCH($A125,'M6'!$K$10:$K$49,0)),"") | C125: =IF(AND(matrizOK,$A125<=nVariables,'M6'!$C$9>0),INDEX('M6'!$H$10:$H$49,MATCH($A125,'M6'!$K$10:$K$49,0)),"") | D125: =IF(AND(matrizOK,$A125<=nVariables,'M6'!$C$9>0),INDEX('M6'!$F$10:$F$49,MATCH($A125,'M6'!$K$10:$K$49,0)),"")
...

Sheet M
A1: M | Matriz de influencias directas (Vester) — la única hoja que usted llena
A2: Cómo llenar: (1) escriba el nombre de cada variable en la columna B, una por fila desde la fila 10, sin dejar filas vacías (mínimo 3, máximo 40; el estándar trae 15 espacios). (2) Valore solo las celdas azul claro: la variable de la FILA influye directamente sobre la variable de la COLUMNA; evalúe también la dirección contraria. Escala: 0 = sin influencia directa; 1 = débil; 2 = moderada; 3 = fuerte; celda vacía = pendiente. Al agregar o quitar nombres, todas las hojas se reconfiguran solas.
A3: =IF(matrizOK,"M completa y válida: "&$C$4&" variables y "&$G$4&" valoraciones. Los resultados están calculados."&IF($G$5>0," Aviso: hay "&$G$5&" nombres repetidos.","")&IF($K$5>0," Aviso: hay "&$K$5&" valores fuera de la matriz activa; se ignoran (bórrelos si ya no los necesita).",""),IF($C$5>0,"REVISAR: hay nombres debajo de una fila vacía. Llene o borre esa fila para que se cuenten todas las variables.",IF($C$4<3,"Escriba al menos 3 nombres de variables en B10 hacia abajo (máximo 40).",IF($O$5>0,"REVISAR: la diagonal debe valer 0 (déjela como está: se completa sola).","REVISAR M:"&IF($G$4>$K$4," valoraciones pendientes o con texto: "&($G$4-$K$4)&".","")&IF($K$4>$O$4," valores que no son enteros de 0 a 3: "&($K$4-$O$4)&" (celdas oscuras).","")))))
B4: Variables detectadas (N) | C4: =SUM(AS10:AS49) | D4: Valoraciones necesarias | G4: =$C$4*($C$4-1) | H4: Valoraciones numéricas | K4: =SUMPRODUCT(($A$10:$A$49<=$C$4)*($D$7:$AQ$7<=$C$4)*($A$10:$A$49<>$D$7:$AQ$7)*ISNUMBER($D$10:$AQ$49)) | L4: Valoraciones válidas (0–3) | O4: =SUMPRODUCT(($A$10:$A$49<=$C$4)*($D$7:$AQ$7<=$C$4)*($A$10:$A$49<>$D$7:$AQ$7)*ISNUMBER($D$10:$AQ$49)*(($D$10:$AQ$49=0)+($D$10:$AQ$49=1)+($D$10:$AQ$49=2)+($D$10:$AQ$49=3)))
B5: Nombres debajo de una fila vacía | C5: =SUMPRODUCT(--(TRIM($B$10:$B$49)<>""))-$C$4 | D5: Nombres repetidos | G5: =COUNTIF($AU$10:$AU$49,">1") | H5: Valores fuera de la matriz | K5: =SUMPRODUCT(ISNUMBER($D$10:$AQ$49)*(1-($A$10:$A$49<=$C$4)*($D$7:$AQ$7<=$C$4))) | L5: Diagonal distinta de 0 | O5: =SUMPRODUCT(($A$10:$A$49=$D$7:$AQ$7)*($A$10:$A$49<=$C$4)*ISNUMBER($D$10:$AQ$49)*($D$10:$AQ$49<>0))
B6: M lista para calcular | C6: =AND($C$4>=3,$C$5=0,$K$4=$G$4,$O$4=$G$4,$O$5=0) | D6: Nombre del estudio (opcional) | G6: SGR_CONV56_AIRE · S_TRABAJO_PROPUESTO (fichas paritarias, no ratificado)
D7: 1 | E7: 2 | F7: 3 | G7: 4 | H7: 5 | I7: 6 | J7: 7 | K7: 8 | L7: 9 | M7: 10 | N7: 11 | O7: 12 | P7: 13 | Q7: 14 | R7: 15 | S7: 16 | T7: 17 | U7: 18 | V7: 19 | W7: 20 | X7: 21 | Y7: 22 | Z7: 23 | AA7: 24 | AB7: 25 | AC7: 26 | AD7: 27 | AE7: 28 | AF7: 29 | AG7: 30 | AH7: 31 | AI7: 32 | AJ7: 33 | AK7: 34 | AL7: 35 | AM7: 36 | AN7: 37 | AO7: 38 | AP7: 39 | AQ7: 40
A8: N.º | B8: Variable (escriba aquí el nombre completo) | C8: Etiqueta corta (opcional, ≤ 20 caracteres) | D8: =IF(D$7<=$C$4,INDEX($AT$10:$AT$49,D$7),"") | E8: =IF(E$7<=$C$4,INDEX($AT$10:$AT$49,E$7),"") | F8: =IF(F$7<=$C$4,INDEX($AT$10:$AT$49,F$7),"") | G8: =IF(G$7<=$C$4,INDEX($AT$10:$AT$49,G$7),"") | H8: =IF(H$7<=$C$4,INDEX($AT$10:$AT$49,H$7),"") | I8: =IF(I$7<=$C$4,INDEX($AT$10:$AT$49,I$7),"") | J8: =IF(J$7<=$C$4,INDEX($AT$10:$AT$49,J$7),"") | K8: =IF(K$7<=$C$4,INDEX($AT$10:$AT$49,K$7),"") | ... S8: =IF(S$7<=$C$4,INDEX($AT$10:$AT$49,S$7),"") | AN8: =IF(AN$7<=$C$4,INDEX($AT$10:$AT$49,AN$7),"") | AO8: =IF(AO$7<=$C$4,INDEX($AT$10:$AT$49,AO$7),"") | AP8: =IF(AP$7<=$C$4,INDEX($AT$10:$AT$49,AP$7),"") | AQ8: =IF(AQ$7<=$C$4,INDEX($AT$10:$AT$49,AQ$7),"") | AS8: Aux: nombre contiguo | AT8: Aux: etiqueta | AU8: Aux: repetidos
B9: Dependencia directa (Σ de cada columna) | D9: =IF(D$7<=$C$4,SUMPRODUCT(($A$10:$A$49<=$C$4)*($A$10:$A$49<>D$7),D10:D49),"") | E9: =IF(E$7<=$C$4,SUMPRODUCT(($A$10:$A$49<=$C$4)*($A$10:$A$49<>E$7),E10:E49),"") | F9: =IF(F$7<=$C$4,SUMPRODUCT(($A$10:$A$49<=$C$4)*($A$10:$A$49<>F$7),F10:F49),"") | G9: =IF(G$7<=$C$4,SUMPRODUCT(($A$10:$A$49<=$C$4)*($A$10:$A$49<>G$7),G10:G49),"") | H9: =IF(H$7<=$C$4,SUMPRODUCT(($A$10:$A$49<=$C$4)*($A$10:$A$49<>H$7),H10:H49),"") | I9: =IF(I$7<=$C$4,SUMPRODUCT(($A$10:$A$49<=$C$4)*($A$10:$A$49<>I$7),I10:I49),"") | J9: =IF(J$7<=$C$4,SUMPRODUCT(($A$10:$A$49<=$C$4)*($A$10:$A$49<>J$7),J10:J49),"") | K9: =IF(K$7<=$C$4,SUMPRODUCT(($A$10:$A$49<=$C$4)*($A$10:$A$49<>K$7),K10:K49),"") | ... S9: =IF(S$7<=$C$4,SUMPRODUCT(($A$10:$A$49<=$C$4)*($A$10:$A$49<>S$7),S10:S49),"") | AN9: =IF(AN$7<=$C$4,SUMPRODUCT(($A$10:$A$49<=$C$4)*($A$10:$A$49<>AN$7),AN10:AN49),"") | AO9: =IF(AO$7<=$C$4,SUMPRODUCT(($A$10:$A$49<=$C$4)*($A$10:$A$49<>AO$7),AO10:AO49),"") | AP9: =IF(AP$7<=$C$4,SUMPRODUCT(($A$10:$A$49<=$C$4)*($A$10:$A$49<>AP$7),AP10:AP49),"") | AQ9: =IF(AQ$7<=$C$4,SUMPRODUCT(($A$10:$A$49<=$C$4)*($A$10:$A$49<>AQ$7),AQ10:AQ49),"")
A10: 1 | B10: Concentración PM2.5 | C10: Masa de partículas <2.5 µm (µg/m³). | D10: 0 | E10: 0 | F10: 0 | G10: 0 | H10: 0 | I10: 2 | J10: 0 | K10: 0 | L10: 0 | M10: 0 | N10: 3 | O10: 0 | P10: 0 | Q10: 1 | R10: 0 | AS10: =IF(AND(TRIM(B10)<>"",1=1),1,0) | AT10: =IF(AS10=1,A10&". "&IF(TRIM(C10)<>"",TRIM(C10),IF(LEN(TRIM(B10))>18,LEFT(TRIM(B10),17)&"…",TRIM(B10))),"") | AU10: =IF(AS10=1,COUNTIF($B$10:$B$49,B10),0)
A11: 2 | B11: Concentración PM10 | C11: Masa de partículas <10 µm (µg/m³). | D11: 0 | E11: 0 | F11: 0 | G11: 0 | H11: 0 | I11: 3 | J11: 0 | K11: 0 | L11: 1 | M11: 0 | N11: 2 | O11: 0 | P11: 0 | Q11: 1 | R11: 0 | AS11: =IF(AND(TRIM(B11)<>"",AS10=1),1,0) | AT11: =IF(AS11=1,A11&". "&IF(TRIM(C11)<>"",TRIM(C11),IF(LEN(TRIM(B11))>18,LEFT(TRIM(B11),17)&"…",TRIM(B11))),"") | AU11: =IF(AS11=1,COUNTIF($B$10:$B$49,B11),0)
A12: 3 | B12: Humedad Relativa | C12: Saturación de vapor de agua (%). | D12: 1 | E12: 1 | F12: 0 | G12: 0 | H12: 0 | I12: 3 | J12: 0 | K12: 0 | L12: 1 | M12: 0 | N12: 0 | O12: 0 | P12: 0 | Q12: 0 | R12: 0 | AS12: =IF(AND(TRIM(B12)<>"",AS11=1),1,0) | AT12: =IF(AS12=1,A12&". "&IF(TRIM(C12)<>"",TRIM(C12),IF(LEN(TRIM(B12))>18,LEFT(TRIM(B12),17)&"…",TRIM(B12))),"") | AU12: =IF(AS12=1,COUNTIF($B$10:$B$49,B12),0)
A13: 4 | B13: Velocidad Viento | C13: Fuerza de dispersión eólica superficial (m/s). | D13: 2 | E13: 2 | F13: 0 | G13: 0 | H13: 0 | I13: 1 | J13: 0 | K13: 1 | L13: 1 | M13: 0 | N13: 0 | O13: 0 | P13: 1 | Q13: 0 | R13: 0 | AS13: =IF(AND(TRIM(B13)<>"",AS12=1),1,0) | AT13: =IF(AS13=1,A13&". "&IF(TRIM(C13)<>"",TRIM(C13),IF(LEN(TRIM(B13))>18,LEFT(TRIM(B13),17)&"…",TRIM(B13))),"") | AU13: =IF(AS13=1,COUNTIF($B$10:$B$49,B13),0)
A14: 5 | B14: Vol. Escombros | C14: Residuos removidos post-sismo (t/día). | D14: 2 | E14: 3 | F14: 0 | G14: 0 | H14: 0 | I14: 0 | J14: 0 | K14: 0 | L14: 2 | M14: 0 | N14: 0 | O14: 0 | P14: 0 | Q14: 0 | R14: 0 | AS14: =IF(AND(TRIM(B14)<>"",AS13=1),1,0) | AT14: =IF(AS14=1,A14&". "&IF(TRIM(C14)<>"",TRIM(C14),IF(LEN(TRIM(B14))>18,LEFT(TRIM(B14),17)&"…",TRIM(B14))),"") | AU14: =IF(AS14=1,COUNTIF($B$10:$B$49,B14),0)
A15: 6 | B15: Error Medición IoT | C15: Desfase metrológico del sensor láser (NMAE %). | D15: 0 | E15: 0 | F15: 0 | G15: 0 | H15: 0 | I15: 0 | J15: 1 | K15: 0 | L15: 1 | M15: 0 | N15: 3 | O15: 2 | P15: 0 | Q15: 0 | R15: 1 | AS15: =IF(AND(TRIM(B15)<>"",AS14=1),1,0) | AT15: =IF(AS15=1,A15&". "&IF(TRIM(C15)<>"",TRIM(C15),IF(LEN(TRIM(B15))>18,LEFT(TRIM(B15),17)&"…",TRIM(B15))),"") | AU15: =IF(AS15=1,COUNTIF($B$10:$B$49,B15),0)
A16: 7 | B16: Frec. Calibración | C16: Tasa de ajuste algorítmico del gemelo (Ajustes/sem). | D16: 0 | E16: 0 | F16: 0 | G16: 0 | H16: 0 | I16: 3 | J16: 0 | K16: 1 | L16: 1 | M16: 0 | N16: 0 | O16: 0 | P16: 0 | Q16: 0 | R16: 0 | AS16: =IF(AND(TRIM(B16)<>"",AS15=1),1,0) | AT16: =IF(AS16=1,A16&". "&IF(TRIM(C16)<>"",TRIM(C16),IF(LEN(TRIM(B16))>18,LEFT(TRIM(B16),17)&"…",TRIM(B16))),"") | AU16: =IF(AS16=1,COUNTIF($B$10:$B$49,B16),0)
A17: 8 | B17: Latencia Datos | C17: Retraso en transmisión a la nube central (minutos). | D17: 0 | E17: 0 | F17: 0 | G17: 0 | H17: 0 | I17: 0 | J17: 0 | K17: 0 | L17: 0 | M17: 0 | N17: 0 | O17: 0 | P17: 2 | Q17: 0 | R17: 0 | AS17: =IF(AND(TRIM(B17)<>"",AS16=1),1,0) | AT17: =IF(AS17=1,A17&". "&IF(TRIM(C17)<>"",TRIM(C17),IF(LEN(TRIM(B17))>18,LEFT(TRIM(B17),17)&"…",TRIM(B17))),"") | AU17: =IF(AS17=1,COUNTIF($B$10:$B$49,B17),0)
A18: 9 | B18: Disp. Nodos IoT | C18: Porcentaje de la red de sensores activa y con energía (%). | D18: 0 | E18: 0 | F18: 0 | G18: 0 | H18: 0 | I18: 0 | J18: 0 | K18: 0 | L18: 0 | M18: 3 | N18: 0 | O18: 0 | P18: 0 | Q18: 0 | R18: 1 | AS18: =IF(AND(TRIM(B18)<>"",AS17=1),1,0) | AT18: =IF(AS18=1,A18&". "&IF(TRIM(C18)<>"",TRIM(C18),IF(LEN(TRIM(B18))>18,LEFT(TRIM(B18),17)&"…",TRIM(B18))),"") | AU18: =IF(AS18=1,COUNTIF($B$10:$B$49,B18),0)
A19: 10 | B19: Densidad Gemelo | C19: Resolución del mapa predictivo espacial (nodos/km²). | D19: 0 | E19: 0 | F19: 0 | G19: 0 | H19: 0 | I19: 1 | J19: 0 | K19: 0 | L19: 0 | M19: 0 | N19: 2 | O19: 1 | P19: 1 | Q19: 0 | R19: 0 | AS19: =IF(AND(TRIM(B19)<>"",AS18=1),1,0) | AT19: =IF(AS19=1,A19&". "&IF(TRIM(C19)<>"",TRIM(C19),IF(LEN(TRIM(B19))>18,LEFT(TRIM(B19),17)&"…",TRIM(B19))),"") | AU19: =IF(AS19=1,COUNTIF($B$10:$B$49,B19),0)
A20: 11 | B20: Índice AQHI | C20: Nivel de peligro de salud pública emitido (1-10). | D20: 0 | E20: 0 | F20: 0 | G20: 0 | H20: 0 | I20: 0 | J20: 0 | K20: 0 | L20: 0 | M20: 0 | N20: 0 | O20: 2 | P20: 0 | Q20: 2 | R20: 1 | AS20: =IF(AND(TRIM(B20)<>"",AS19=1),1,0) | AT20: =IF(AS20=1,A20&". "&IF(TRIM(C20)<>"",TRIM(C20),IF(LEN(TRIM(B20))>18,LEFT(TRIM(B20),17)&"…",TRIM(B20))),"") | AU20: =IF(AS20=1,COUNTIF($B$10:$B$49,B20),0)
A21: 12 | B21: Falsas Alarmas | C21: Tasa de alertas emitidas sin superación de umbral real (%). | D21: 0 | E21: 0 | F21: 0 | G21: 0 | H21: 0 | I21: 0 | J21: 0 | K21: 0 | L21: 0 | M21: 0 | N21: 1 | O21: 0 | P21: 0 | Q21: 1 | R21: 2 | AS21: =IF(AND(TRIM(B21)<>"",AS20=1),1,0) | AT21: =IF(AS21=1,A21&". "&IF(TRIM(C21)<>"",TRIM(C21),IF(LEN(TRIM(B21))>18,LEFT(TRIM(B21),17)&"…",TRIM(B21))),"") | AU21: =IF(AS21=1,COUNTIF($B$10:$B$49,B21),0)
A22: 13 | B22: Anticipación | C22: Tiempo de aviso preventivo antes del impacto (Horas). | D22: 0 | E22: 0 | F22: 0 | G22: 0 | H22: 0 | I22: 0 | J22: 0 | K22: 0 | L22: 0 | M22: 0 | N22: 0 | O22: 0 | P22: 0 | Q22: 2 | R22: 0 | AS22: =IF(AND(TRIM(B22)<>"",AS21=1),1,0) | AT22: =IF(AS22=1,A22&". "&IF(TRIM(C22)<>"",TRIM(C22),IF(LEN(TRIM(B22))>18,LEFT(TRIM(B22),17)&"…",TRIM(B22))),"") | AU22: =IF(AS22=1,COUNTIF($B$10:$B$49,B22),0)
... A24: 15 | B24: Adopción Institucional | C24: Uso efectivo del tablero por alcaldías/UNGRD (%). | D24: 0 | E24: 0 | F24: 0 | G24: 0 | H24: 1 | I24: 0 | J24: 1 | K24: 0 | L24: 2 | M24: 1 | N24: 0 | O24: 0 | P24: 0 | Q24: 2 | R24: 0 | AS24: =IF(AND(TRIM(B24)<>"",AS23=1),1,0) | AT24: =IF(AS24=1,A24&". "&IF(TRIM(C24)<>"",TRIM(C24),IF(LEN(TRIM(B24))>18,LEFT(TRIM(B24),17)&"…",TRIM(B24))),"") | AU24: =IF(AS24=1,COUNTIF($B$10:$B$49,B24),0)
A25: 16 | S25: =IF($A25<=$C$4,0,"") | AS25: =IF(AND(TRIM(B25)<>"",AS24=1),1,0) | AT25: =IF(AS25=1,A25&". "&IF(TRIM(C25)<>"",TRIM(C25),IF(LEN(TRIM(B25))>18,LEFT(TRIM(B25),17)&"…",TRIM(B25))),"") | AU25: =IF(AS25=1,COUNTIF($B$10:$B$49,B25),0)
A26: 17 | AS26: =IF(AND(TRIM(B26)<>"",AS25=1),1,0) | AT26: =IF(AS26=1,A26&". "&IF(TRIM(C26)<>"",TRIM(C26),IF(LEN(TRIM(B26))>18,LEFT(TRIM(B26),17)&"…",TRIM(B26))),"") | AU26: =IF(AS26=1,COUNTIF($B$10:$B$49,B26),0)
A27: 18 | AS27: =IF(AND(TRIM(B27)<>"",AS26=1),1,0) | AT27: =IF(AS27=1,A27&". "&IF(TRIM(C27)<>"",TRIM(C27),IF(LEN(TRIM(B27))>18,LEFT(TRIM(B27),17)&"…",TRIM(B27))),"") | AU27: =IF(AS27=1,COUNTIF($B$10:$B$49,B27),0)
A28: 19 | AS28: =IF(AND(TRIM(B28)<>"",AS27=1),1,0) | AT28: =IF(AS28=1,A28&". "&IF(TRIM(C28)<>"",TRIM(C28),IF(LEN(TRIM(B28))>18,LEFT(TRIM(B28),17)&"…",TRIM(B28))),"") | AU28: =IF(AS28=1,COUNTIF($B$10:$B$49,B28),0)
A29: 20 | AS29: =IF(AND(TRIM(B29)<>"",AS28=1),1,0) | AT29: =IF(AS29=1,A29&". "&IF(TRIM(C29)<>"",TRIM(C29),IF(LEN(TRIM(B29))>18,LEFT(TRIM(B29),17)&"…",TRIM(B29))),"") | AU29: =IF(AS29=1,COUNTIF($B$10:$B$49,B29),0)
A30: 21 | AS30: =IF(AND(TRIM(B30)<>"",AS29=1),1,0) | AT30: =IF(AS30=1,A30&". "&IF(TRIM(C30)<>"",TRIM(C30),IF(LEN(TRIM(B30))>18,LEFT(TRIM(B30),17)&"…",TRIM(B30))),"") | AU30: =IF(AS30=1,COUNTIF($B$10:$B$49,B30),0)
A31: 22 | Y31: =IF($A31<=$C$4,0,"") | AS31: =IF(AND(TRIM(B31)<>"",AS30=1),1,0) | AT31: =IF(AS31=1,A31&". "&IF(TRIM(C31)<>"",TRIM(C31),IF(LEN(TRIM(B31))>18,LEFT(TRIM(B31),17)&"…",TRIM(B31))),"") | AU31: =IF(AS31=1,COUNTIF($B$10:$B$49,B31),0)
A32: 23 | Z32: =IF($A32<=$C$4,0,"") | AS32: =IF(AND(TRIM(B32)<>"",AS31=1),1,0) | AT32: =IF(AS32=1,A32&". "&IF(TRIM(C32)<>"",TRIM(C32),IF(LEN(TRIM(B32))>18,LEFT(TRIM(B32),17)&"…",TRIM(B32))),"") | AU32: =IF(AS32=1,COUNTIF($B$10:$B$49,B32),0)
A33: 24 | AA33: =IF($A33<=$C$4,0,"") | AS33: =IF(AND(TRIM(B33)<>"",AS32=1),1,0) | AT33: =IF(AS33=1,A33&". "&IF(TRIM(C33)<>"",TRIM(C33),IF(LEN(TRIM(B33))>18,LEFT(TRIM(B33),17)&"…",TRIM(B33))),"") | AU33: =IF(AS33=1,COUNTIF($B$10:$B$49,B33),0)
A34: 25 | AB34: =IF($A34<=$C$4,0,"") | AS34: =IF(AND(TRIM(B34)<>"",AS33=1),1,0) | AT34: =IF(AS34=1,A34&". "&IF(TRIM(C34)<>"",TRIM(C34),IF(LEN(TRIM(B34))>18,LEFT(TRIM(B34),17)&"…",TRIM(B34))),"") | AU34: =IF(AS34=1,COUNTIF($B$10:$B$49,B34),0)
A35: 26 | AC35: =IF($A35<=$C$4,0,"") | AS35: =IF(AND(TRIM(B35)<>"",AS34=1),1,0) | AT35: =IF(AS35=1,A35&". "&IF(TRIM(C35)<>"",TRIM(C35),IF(LEN(TRIM(B35))>18,LEFT(TRIM(B35),17)&"…",TRIM(B35))),"") | AU35: =IF(AS35=1,COUNTIF($B$10:$B$49,B35),0)
A36: 27 | AD36: =IF($A36<=$C$4,0,"") | AS36: =IF(AND(TRIM(B36)<>"",AS35=1),1,0) | AT36: =IF(AS36=1,A36&". "&IF(TRIM(C36)<>"",TRIM(C36),IF(LEN(TRIM(B36))>18,LEFT(TRIM(B36),17)&"…",TRIM(B36))),"") | AU36: =IF(AS36=1,COUNTIF($B$10:$B$49,B36),0)
A37: 28 | AE37: =IF($A37<=$C$4,0,"") | AS37: =IF(AND(TRIM(B37)<>"",AS36=1),1,0) | AT37: =IF(AS37=1,A37&". "&IF(TRIM(C37)<>"",TRIM(C37),IF(LEN(TRIM(B37))>18,LEFT(TRIM(B37),17)&"…",TRIM(B37))),"") | AU37: =IF(AS37=1,COUNTIF($B$10:$B$49,B37),0)
A38: 29 | AF38: =IF($A38<=$C$4,0,"") | AS38: =IF(AND(TRIM(B38)<>"",AS37=1),1,0) | AT38: =IF(AS38=1,A38&". "&IF(TRIM(C38)<>"",TRIM(C38),IF(LEN(TRIM(B38))>18,LEFT(TRIM(B38),17)&"…",TRIM(B38))),"") | AU38: =IF(AS38=1,COUNTIF($B$10:$B$49,B38),0)
A39: 30 | AG39: =IF($A39<=$C$4,0,"") | AS39: =IF(AND(TRIM(B39)<>"",AS38=1),1,0) | AT39: =IF(AS39=1,A39&". "&IF(TRIM(C39)<>"",TRIM(C39),IF(LEN(TRIM(B39))>18,LEFT(TRIM(B39),17)&"…",TRIM(B39))),"") | AU39: =IF(AS39=1,COUNTIF($B$10:$B$49,B39),0)
A40: 31 | AH40: =IF($A40<=$C$4,0,"") | AS40: =IF(AND(TRIM(B40)<>"",AS39=1),1,0) | AT40: =IF(AS40=1,A40&". "&IF(TRIM(C40)<>"",TRIM(C40),IF(LEN(TRIM(B40))>18,LEFT(TRIM(B40),17)&"…",TRIM(B40))),"") | AU40: =IF(AS40=1,COUNTIF($B$10:$B$49,B40),0)
A41: 32 | AI41: =IF($A41<=$C$4,0,"") | AS41: =IF(AND(TRIM(B41)<>"",AS40=1),1,0) | AT41: =IF(AS41=1,A41&". "&IF(TRIM(C41)<>"",TRIM(C41),IF(LEN(TRIM(B41))>18,LEFT(TRIM(B41),17)&"…",TRIM(B41))),"") | AU41: =IF(AS41=1,COUNTIF($B$10:$B$49,B41),0)
...

Sheet M1
A1: M1 | Relaciones directas · M¹ = M
A2: Esta hoja reproduce M. No representa otra valoración: es la primera potencia de la misma matriz. Fila = influencia ejercida; columna = dependencia recibida. La suma de cada una resume las valoraciones del grupo.
A3: =IF(matrizOK,IF($C$9=0,"Sin recorridos en esta potencia. No hay porcentajes, rangos ni clasificación.","Cálculo disponible para "&nVariables&" variables. Lea las filas y las columnas por separado."),"Complete y corrija M para obtener resultados.")
B4: Variables (N) | C4: =nVariables | D4: Mediana de influencia | F4: =$C$51
B5: Total de pesos (Σ de toda la matriz) | C5: =$C$9 | D5: Mediana de dependencia | F5: =$D$51
M7: 1 | N7: 2 | O7: 3 | P7: 4 | Q7: 5 | R7: 6 | S7: 7 | T7: 8 | U7: 9 | V7: 10 | W7: 11 | X7: 12 | Y7: 13 | Z7: 14 | AA7: 15 | AB7: 16 | AC7: 17 | AD7: 18 | AE7: 19 | AF7: 20 | AG7: 21 | AH7: 22 | AI7: 23 | AJ7: 24 | AK7: 25 | AL7: 26 | AM7: 27 | AN7: 28 | AO7: 29 | AP7: 30 | AQ7: 31 | AR7: 32 | AS7: 33 | AT7: 34 | AU7: 35 | AV7: 36 | AW7: 37 | AX7: 38 | AY7: 39 | AZ7: 40
A8: N.º | B8: Variable (origen ↓ / destino →) | C8: Influencia (Σ fila) | D8: Dependencia (Σ columna) | E8: Influencia % | F8: Dependencia % | G8: Rango influencia | H8: Rango dependencia | I8: Papel relativo | J8: Orden visual I | K8: Orden visual D | M8: =IF(M$7<=nVariables,INDEX(M!$AT$10:$AT$49,M$7),"") | N8: =IF(N$7<=nVariables,INDEX(M!$AT$10:$AT$49,N$7),"") | O8: =IF(O$7<=nVariables,INDEX(M!$AT$10:$AT$49,O$7),"") | P8: =IF(P$7<=nVariables,INDEX(M!$AT$10:$AT$49,P$7),"") | Q8: =IF(Q$7<=nVariables,INDEX(M!$AT$10:$AT$49,Q$7),"") | R8: =IF(R$7<=nVariables,INDEX(M!$AT$10:$AT$49,R$7),"") | S8: =IF(S$7<=nVariables,INDEX(M!$AT$10:$AT$49,S$7),"") | T8: =IF(T$7<=nVariables,INDEX(M!$AT$10:$AT$49,T$7),"") | ... AZ8: =IF(AZ$7<=nVariables,INDEX(M!$AT$10:$AT$49,AZ$7),"")
B9: Total general · dependencia de cada columna → | C9: =IF(matrizOK,SUM(M10:AZ49),0) | M9: =IF(M$7<=nVariables,SUM(M10:M49),"") | N9: =IF(N$7<=nVariables,SUM(N10:N49),"") | O9: =IF(O$7<=nVariables,SUM(O10:O49),"") | P9: =IF(P$7<=nVariables,SUM(P10:P49),"") | Q9: =IF(Q$7<=nVariables,SUM(Q10:Q49),"") | R9: =IF(R$7<=nVariables,SUM(R10:R49),"") | S9: =IF(S$7<=nVariables,SUM(S10:S49),"") | T9: =IF(T$7<=nVariables,SUM(T10:T49),"") | ... AZ9: =IF(AZ$7<=nVariables,SUM(AZ10:AZ49),"")
A10: 1 | B10: =IF($A10<=nVariables,M!$B10,"") | C10: =IF(AND(matrizOK,$A10<=nVariables),SUM($M10:$AZ10),"") | D10: =IF(AND(matrizOK,$A10<=nVariables),INDEX($M$9:$AZ$9,$A10),"") | E10: =IF(AND(matrizOK,$A10<=nVariables,$C$9>0),C10/$C$9,"") | F10: =IF(AND(matrizOK,$A10<=nVariables,$C$9>0),D10/$C$9,"") | G10: =IF(AND(matrizOK,$A10<=nVariables,$C$9>0),1+COUNTIF($C$10:$C$49,">"&C10),"") | H10: =IF(AND(matrizOK,$A10<=nVariables,$C$9>0),1+COUNTIF($D$10:$D$49,">"&D10),"") | I10: =IF(AND(matrizOK,$A10<=nVariables),IF($C$9=0,"Sin recorridos",IF(OR($C$51=0,$D$51=0),"Corte no interpretable",IF(C10>=$C$51,IF(D10>=$D$51,"Enlace","Motriz"),IF(D10>=$D$51,"Resultado","Autónoma")))),"") | J10: =IF(AND(matrizOK,$A10<=nVariables,$C$9>0),G10+COUNTIF($C$10:C10,C10)-1,"") | K10: =IF(AND(matrizOK,$A10<=nVariables,$C$9>0),H10+COUNTIF($D$10:D10,D10)-1,"") | M10: =IF(AND(matrizOK,$A10<=nVariables,M$7<=nVariables,$A10<>M$7),M!D10,0) | N10: =IF(AND(matrizOK,$A10<=nVariables,N$7<=nVariables,$A10<>N$7),M!E10,0) | O10: =IF(AND(matrizOK,$A10<=nVariables,O$7<=nVariables,$A10<>O$7),M!F10,0) | P10: =IF(AND(matrizOK,$A10<=nVariables,P$7<=nVariables,$A10<>P$7),M!G10,0) | Q10: =IF(AND(matrizOK,$A10<=nVariables,Q$7<=nVariables,$A10<>Q$7),M!H10,0) | R10: =IF(AND(matrizOK,$A10<=nVariables,R$7<=nVariables,$A10<>R$7),M!I10,0) | S10: =IF(AND(matrizOK,$A10<=nVariables,S$7<=nVariables,$A10<>S$7),M!J10,0) | T10: =IF(AND(matrizOK,$A10<=nVariables,T$7<=nVariables,$A10<>T$7),M!K10,0) | ... AC10: =IF(AND(matrizOK,$A10<=nVariables,AC$7<=nVariables,$A10<>AC$7),M!T10,0) | AD10: =IF(AND(matrizOK,$A10<=nVariables,AD$7<=nVariables,$A10<>AD$7),M!V10,0) | AE10: =IF(AND(matrizOK,$A10<=nVariables,AE$7<=nVariables,$A10<>AE$7),M!W10,0) | AF10: =IF(AND(matrizOK,$A10<=nVariables,AF$7<=nVariables,$A10<>AF$7),M!#REF!,0) | AG10: =IF(AND(matrizOK,$A10<=nVariables,AG$7<=nVariables,$A10<>AG$7),M!X10,0) | AH10: =IF(AND(matrizOK,$A10<=nVariables,AH$7<=nVariables,$A10<>AH$7),M!Y10,0) | AI10: =IF(AND(matrizOK,$A10<=nVariables,AI$7<=nVariables,$A10<>AI$7),M!Z10,0) | AJ10: =IF(AND(matrizOK,$A10<=nVariables,AJ$7<=nVariables,$A10<>AJ$7),M!AA10,0) | AK10: =IF(AND(matrizOK,$A10<=nVariables,AK$7<=nVariables,$A10<>AK$7),M!AB10,0) | AL10: =IF(AND(matrizOK,$A10<=nVariables,AL$7<=nVariables,$A10<>AL$7),M!AC10,0) | AM10: =IF(AND(matrizOK,$A10<=nVariables,AM$7<=nVariables,$A10<>AM$7),M!AD10,0) | AN10: =IF(AND(matrizOK,$A10<=nVariables,AN$7<=nVariables,$A10<>AN$7),M!AE10,0) | ... AZ10: =IF(AND(matrizOK,$A10<=nVariables,AZ$7<=nVariables,$A10<>AZ$7),M!AQ10,0)
A11: 2 | B11: =IF($A11<=nVariables,M!$B11,"") | C11: =IF(AND(matrizOK,$A11<=nVariables),SUM($M11:$AZ11),"") | D11: =IF(AND(matrizOK,$A11<=nVariables),INDEX($M$9:$AZ$9,$A11),"") | E11: =IF(AND(matrizOK,$A11<=nVariables,$C$9>0),C11/$C$9,"") | F11: =IF(AND(matrizOK,$A11<=nVariables,$C$9>0),D11/$C$9,"") | G11: =IF(AND(matrizOK,$A11<=nVariables,$C$9>0),1+COUNTIF($C$10:$C$49,">"&C11),"") | H11: =IF(AND(matrizOK,$A11<=nVariables,$C$9>0),1+COUNTIF($D$10:$D$49,">"&D11),"") | I11: =IF(AND(matrizOK,$A11<=nVariables),IF($C$9=0,"Sin recorridos",IF(OR($C$51=0,$D$51=0),"Corte no interpretable",IF(C11>=$C$51,IF(D11>=$D$51,"Enlace","Motriz"),IF(D11>=$D$51,"Resultado","Autónoma")))),"") | J11: =IF(AND(matrizOK,$A11<=nVariables,$C$9>0),G11+COUNTIF($C$10:C11,C11)-1,"") | K11: =IF(AND(matrizOK,$A11<=nVariables,$C$9>0),H11+COUNTIF($D$10:D11,D11)-1,"") | M11: =IF(AND(matrizOK,$A11<=nVariables,M$7<=nVariables,$A11<>M$7),M!D11,0) | N11: =IF(AND(matrizOK,$A11<=nVariables,N$7<=nVariables,$A11<>N$7),M!E11,0) | O11: =IF(AND(matrizOK,$A11<=nVariables,O$7<=nVariables,$A11<>O$7),M!F11,0) | P11: =IF(AND(matrizOK,$A11<=nVariables,P$7<=nVariables,$A11<>P$7),M!G11,0) | Q11: =IF(AND(matrizOK,$A11<=nVariables,Q$7<=nVariables,$A11<>Q$7),M!H11,0) | R11: =IF(AND(matrizOK,$A11<=nVariables,R$7<=nVariables,$A11<>R$7),M!I11,0) | S11: =IF(AND(matrizOK,$A11<=nVariables,S$7<=nVariables,$A11<>S$7),M!J11,0) | T11: =IF(AND(matrizOK,$A11<=nVariables,T$7<=nVariables,$A11<>T$7),M!K11,0) | ... AZ11: =IF(AND(matrizOK,$A11<=nVariables,AZ$7<=nVariables,$A11<>AZ$7),M!AQ11,0)
A12: 3 | B12: =IF($A12<=nVariables,M!$B12,"") | C12: =IF(AND(matrizOK,$A12<=nVariables),SUM($M12:$AZ12),"") | D12: =IF(AND(matrizOK,$A12<=nVariables),INDEX($M$9:$AZ$9,$A12),"") | E12: =IF(AND(matrizOK,$A12<=nVariables,$C$9>0),C12/$C$9,"") | F12: =IF(AND(matrizOK,$A12<=nVariables,$C$9>0),D12/$C$9,"") | G12: =IF(AND(matrizOK,$A12<=nVariables,$C$9>0),1+COUNTIF($C$10:$C$49,">"&C12),"") | H12: =IF(AND(matrizOK,$A12<=nVariables,$C$9>0),1+COUNTIF($D$10:$D$49,">"&D12),"") | I12: =IF(AND(matrizOK,$A12<=nVariables),IF($C$9=0,"Sin recorridos",IF(OR($C$51=0,$D$51=0),"Corte no interpretable",IF(C12>=$C$51,IF(D12>=$D$51,"Enlace","Motriz"),IF(D12>=$D$51,"Resultado","Autónoma")))),"") | J12: =IF(AND(matrizOK,$A12<=nVariables,$C$9>0),G12+COUNTIF($C$10:C12,C12)-1,"") | K12: =IF(AND(matrizOK,$A12<=nVariables,$C$9>0),H12+COUNTIF($D$10:D12,D12)-1,"") | M12: =IF(AND(matrizOK,$A12<=nVariables,M$7<=nVariables,$A12<>M$7),M!D12,0) | N12: =IF(AND(matrizOK,$A12<=nVariables,N$7<=nVariables,$A12<>N$7),M!E12,0) | O12: =IF(AND(matrizOK,$A12<=nVariables,O$7<=nVariables,$A12<>O$7),M!F12,0) | P12: =IF(AND(matrizOK,$A12<=nVariables,P$7<=nVariables,$A12<>P$7),M!G12,0) | Q12: =IF(AND(matrizOK,$A12<=nVariables,Q$7<=nVariables,$A12<>Q$7),M!H12,0) | R12: =IF(AND(matrizOK,$A12<=nVariables,R$7<=nVariables,$A12<>R$7),M!I12,0) | S12: =IF(AND(matrizOK,$A12<=nVariables,S$7<=nVariables,$A12<>S$7),M!J12,0) | T12: =IF(AND(matrizOK,$A12<=nVariables,T$7<=nVariables,$A12<>T$7),M!K12,0) | ... AZ12: =IF(AND(matrizOK,$A12<=nVariables,AZ$7<=nVariables,$A12<>AZ$7),M!AQ12,0)
A13: 4 | B13: =IF($A13<=nVariables,M!$B13,"") | C13: =IF(AND(matrizOK,$A13<=nVariables),SUM($M13:$AZ13),"") | D13: =IF(AND(matrizOK,$A13<=nVariables),INDEX($M$9:$AZ$9,$A13),"") | E13: =IF(AND(matrizOK,$A13<=nVariables,$C$9>0),C13/$C$9,"") | F13: =IF(AND(matrizOK,$A13<=nVariables,$C$9>0),D13/$C$9,"") | G13: =IF(AND(matrizOK,$A13<=nVariables,$C$9>0),1+COUNTIF($C$10:$C$49,">"&C13),"") | H13: =IF(AND(matrizOK,$A13<=nVariables,$C$9>0),1+COUNTIF($D$10:$D$49,">"&D13),"") | I13: =IF(AND(matrizOK,$A13<=nVariables),IF($C$9=0,"Sin recorridos",IF(OR($C$51=0,$D$51=0),"Corte no interpretable",IF(C13>=$C$51,IF(D13>=$D$51,"Enlace","Motriz"),IF(D13>=$D$51,"Resultado","Autónoma")))),"") | J13: =IF(AND(matrizOK,$A13<=nVariables,$C$9>0),G13+COUNTIF($C$10:C13,C13)-1,"") | K13: =IF(AND(matrizOK,$A13<=nVariables,$C$9>0),H13+COUNTIF($D$10:D13,D13)-1,"") | M13: =IF(AND(matrizOK,$A13<=nVariables,M$7<=nVariables,$A13<>M$7),M!D13,0) | N13: =IF(AND(matrizOK,$A13<=nVariables,N$7<=nVariables,$A13<>N$7),M!E13,0) | O13: =IF(AND(matrizOK,$A13<=nVariables,O$7<=nVariables,$A13<>O$7),M!F13,0) | P13: =IF(AND(matrizOK,$A13<=nVariables,P$7<=nVariables,$A13<>P$7),M!G13,0) | Q13: =IF(AND(matrizOK,$A13<=nVariables,Q$7<=nVariables,$A13<>Q$7),M!H13,0) | R13: =IF(AND(matrizOK,$A13<=nVariables,R$7<=nVariables,$A13<>R$7),M!I13,0) | S13: =IF(AND(matrizOK,$A13<=nVariables,S$7<=nVariables,$A13<>S$7),M!J13,0) | T13: =IF(AND(matrizOK,$A13<=nVariables,T$7<=nVariables,$A13<>T$7),M!K13,0) | ... AZ13: =IF(AND(matrizOK,$A13<=nVariables,AZ$7<=nVariables,$A13<>AZ$7),M!AQ13,0)
A14: 5 | B14: =IF($A14<=nVariables,M!$B14,"") | C14: =IF(AND(matrizOK,$A14<=nVariables),SUM($M14:$AZ14),"") | D14: =IF(AND(matrizOK,$A14<=nVariables),INDEX($M$9:$AZ$9,$A14),"") | E14: =IF(AND(matrizOK,$A14<=nVariables,$C$9>0),C14/$C$9,"") | F14: =IF(AND(matrizOK,$A14<=nVariables,$C$9>0),D14/$C$9,"") | G14: =IF(AND(matrizOK,$A14<=nVariables,$C$9>0),1+COUNTIF($C$10:$C$49,">"&C14),"") | H14: =IF(AND(matrizOK,$A14<=nVariables,$C$9>0),1+COUNTIF($D$10:$D$49,">"&D14),"") | I14: =IF(AND(matrizOK,$A14<=nVariables),IF($C$9=0,"Sin recorridos",IF(OR($C$51=0,$D$51=0),"Corte no interpretable",IF(C14>=$C$51,IF(D14>=$D$51,"Enlace","Motriz"),IF(D14>=$D$51,"Resultado","Autónoma")))),"") | J14: =IF(AND(matrizOK,$A14<=nVariables,$C$9>0),G14+COUNTIF($C$10:C14,C14)-1,"") | K14: =IF(AND(matrizOK,$A14<=nVariables,$C$9>0),H14+COUNTIF($D$10:D14,D14)-1,"") | M14: =IF(AND(matrizOK,$A14<=nVariables,M$7<=nVariables,$A14<>M$7),M!D14,0) | N14: =IF(AND(matrizOK,$A14<=nVariables,N$7<=nVariables,$A14<>N$7),M!E14,0) | O14: =IF(AND(matrizOK,$A14<=nVariables,O$7<=nVariables,$A14<>O$7),M!F14,0) | P14: =IF(AND(matrizOK,$A14<=nVariables,P$7<=nVariables,$A14<>P$7),M!G14,0) | Q14: =IF(AND(matrizOK,$A14<=nVariables,Q$7<=nVariables,$A14<>Q$7),M!H14,0) | R14: =IF(AND(matrizOK,$A14<=nVariables,R$7<=nVariables,$A14<>R$7),M!I14,0) | S14: =IF(AND(matrizOK,$A14<=nVariables,S$7<=nVariables,$A14<>S$7),M!J14,0) | T14: =IF(AND(matrizOK,$A14<=nVariables,T$7<=nVariables,$A14<>T$7),M!K14,0) | ... AZ14: =IF(AND(matrizOK,$A14<=nVariables,AZ$7<=nVariables,$A14<>AZ$7),M!AQ14,0)
A15: 6 | B15: =IF($A15<=nVariables,M!$B15,"") | C15: =IF(AND(matrizOK,$A15<=nVariables),SUM($M15:$AZ15),"") | D15: =IF(AND(matrizOK,$A15<=nVariables),INDEX($M$9:$AZ$9,$A15),"") | E15: =IF(AND(matrizOK,$A15<=nVariables,$C$9>0),C15/$C$9,"") | F15: =IF(AND(matrizOK,$A15<=nVariables,$C$9>0),D15/$C$9,"") | G15: =IF(AND(matrizOK,$A15<=nVariables,$C$9>0),1+COUNTIF($C$10:$C$49,">"&C15),"") | H15: =IF(AND(matrizOK,$A15<=nVariables,$C$9>0),1+COUNTIF($D$10:$D$49,">"&D15),"") | I15: =IF(AND(matrizOK,$A15<=nVariables),IF($C$9=0,"Sin recorridos",IF(OR($C$51=0,$D$51=0),"Corte no interpretable",IF(C15>=$C$51,IF(D15>=$D$51,"Enlace","Motriz"),IF(D15>=$D$51,"Resultado","Autónoma")))),"") | J15: =IF(AND(matrizOK,$A15<=nVariables,$C$9>0),G15+COUNTIF($C$10:C15,C15)-1,"") | K15: =IF(AND(matrizOK,$A15<=nVariables,$C$9>0),H15+COUNTIF($D$10:D15,D15)-1,"") | M15: =IF(AND(matrizOK,$A15<=nVariables,M$7<=nVariables,$A15<>M$7),M!D15,0) | N15: =IF(AND(matrizOK,$A15<=nVariables,N$7<=nVariables,$A15<>N$7),M!E15,0) | O15: =IF(AND(matrizOK,$A15<=nVariables,O$7<=nVariables,$A15<>O$7),M!F15,0) | P15: =IF(AND(matrizOK,$A15<=nVariables,P$7<=nVariables,$A15<>P$7),M!G15,0) | Q15: =IF(AND(matrizOK,$A15<=nVariables,Q$7<=nVariables,$A15<>Q$7),M!H15,0) | R15: =IF(AND(matrizOK,$A15<=nVariables,R$7<=nVariables,$A15<>R$7),M!I15,0) | S15: =IF(AND(matrizOK,$A15<=nVariables,S$7<=nVariables,$A15<>S$7),M!J15,0) | T15: =IF(AND(matrizOK,$A15<=nVariables,T$7<=nVariables,$A15<>T$7),M!K15,0) | ... AZ15: =IF(AND(matrizOK,$A15<=nVariables,AZ$7<=nVariables,$A15<>AZ$7),M!AQ15,0)
